telegram.ext.updater - INFO - Received signal 2 (SIGINT), stopping...
telegram.ext.dispatcher - ERROR - An uncaught error was raised while processing the update
Traceback (most recent call last):
  File "C:\Users\ito0010\AppData\Local\Programs\Python\Python36\lib\site-packages\telegram\ext\dispatcher.py", line 279, in process_update
    handler.handle_update(update, self)
  File "C:\Users\ito0010\AppData\Local\Programs\Python\Python36\lib\site-packages\telegram\ext\commandhandler.py", line 173, in handle_update
    return self.callback(dispatcher.bot, update, **optional_args)
  File "c:\LearnPython\Lesson2\bot.py", line 28, in planet_user
    update.message.reply_text(ephem.constellation(planet))
ValueError: the sequence specifying a position must have exactly two coordinates
telegram.ext.updater - INFO - Received signal 2 (SIGINT), stopping...
telegram.ext.dispatcher - ERROR - An uncaught error was raised while processing the update
Traceback (most recent call last):
  File "C:\Users\ito0010\AppData\Local\Programs\Python\Python36\lib\site-packages\telegram\ext\dispatcher.py", line 279, in process_update
    handler.handle_update(update, self)
  File "C:\Users\ito0010\AppData\Local\Programs\Python\Python36\lib\site-packages\telegram\ext\commandhandler.py", line 173, in handle_update
    return self.callback(dispatcher.bot, update, **optional_args)
  File "c:\LearnPython\Lesson2\bot.py", line 28, in planet_user
    text = ephem.constellation(planet)
ValueError: the sequence specifying a position must have exactly two coordinates
telegram.ext.updater - INFO - Received signal 2 (SIGINT), stopping...
telegram.ext.dispatcher - ERROR - An uncaught error was raised while processing the update
Traceback (most recent call last):
  File "C:\Users\ito0010\AppData\Local\Programs\Python\Python36\lib\site-packages\telegram\ext\dispatcher.py", line 279, in process_update
    handler.handle_update(update, self)
  File "C:\Users\ito0010\AppData\Local\Programs\Python\Python36\lib\site-packages\telegram\ext\commandhandler.py", line 173, in handle_update
    return self.callback(dispatcher.bot, update, **optional_args)
  File "c:\LearnPython\Lesson2\bot.py", line 28, in planet_user
    text = ephem.planet(now)
AttributeError: module 'ephem' has no attribute 'planet'
telegram.ext.updater - INFO - Received signal 2 (SIGINT), stopping...
telegram.ext.dispatcher - ERROR - An uncaught error was raised while processing the update
Traceback (most recent call last):
  File "C:\Users\ito0010\AppData\Local\Programs\Python\Python36\lib\site-packages\telegram\ext\dispatcher.py", line 279, in process_update
    handler.handle_update(update, self)
  File "C:\Users\ito0010\AppData\Local\Programs\Python\Python36\lib\site-packages\telegram\ext\commandhandler.py", line 173, in handle_update
    return self.callback(dispatcher.bot, update, **optional_args)
  File "c:\LearnPython\Lesson2\bot.py", line 28, in planet_user
    text = ephem.planet(datetime.now)
AttributeError: module 'ephem' has no attribute 'planet'
telegram.ext.dispatcher - ERROR - An uncaught error was raised while processing the update
Traceback (most recent call last):
  File "C:\Users\ito0010\AppData\Local\Programs\Python\Python36\lib\site-packages\telegram\ext\dispatcher.py", line 279, in process_update
    handler.handle_update(update, self)
  File "C:\Users\ito0010\AppData\Local\Programs\Python\Python36\lib\site-packages\telegram\ext\commandhandler.py", line 173, in handle_update
    return self.callback(dispatcher.bot, update, **optional_args)
  File "c:\LearnPython\Lesson2\bot.py", line 28, in planet_user
    today = datetime.strftime(datetime.now(), '%Y/%m/%d')
AttributeError: module 'datetime' has no attribute 'strftime'
telegram.ext.updater - ERROR - Error while getting Updates: Conflict: terminated by other getUpdates request; make sure that only one bot instance is running (409)
telegram.ext.dispatcher - ERROR - No error handlers are registered, logging exception.
Traceback (most recent call last):
  File "C:\Users\ito0010\AppData\Local\Programs\Python\Python36\lib\site-packages\telegram\ext\updater.py", line 319, in _network_loop_retry
    if not action_cb():
  File "C:\Users\ito0010\AppData\Local\Programs\Python\Python36\lib\site-packages\telegram\ext\updater.py", line 280, in polling_action_cb
    allowed_updates=allowed_updates)
  File "C:\Users\ito0010\AppData\Local\Programs\Python\Python36\lib\site-packages\telegram\bot.py", line 65, in decorator
    result = func(self, *args, **kwargs)
  File "C:\Users\ito0010\AppData\Local\Programs\Python\Python36\lib\site-packages\telegram\bot.py", line 1975, in get_updates
    result = self._request.post(url, data, timeout=float(read_latency) + float(timeout))
  File "C:\Users\ito0010\AppData\Local\Programs\Python\Python36\lib\site-packages\telegram\utils\request.py", line 309, in post
    headers={'Content-Type': 'application/json'})
  File "C:\Users\ito0010\AppData\Local\Programs\Python\Python36\lib\site-packages\telegram\utils\request.py", line 233, in _request_wrapper
    raise NetworkError('{0} ({1})'.format(message, resp.status))
telegram.error.NetworkError: Conflict: terminated by other getUpdates request; make sure that only one bot instance is running (409)
telegram.ext.dispatcher - ERROR - An uncaught error was raised while processing the update
Traceback (most recent call last):
  File "C:\Users\ito0010\AppData\Local\Programs\Python\Python36\lib\site-packages\telegram\ext\dispatcher.py", line 279, in process_update
    handler.handle_update(update, self)
  File "C:\Users\ito0010\AppData\Local\Programs\Python\Python36\lib\site-packages\telegram\ext\commandhandler.py", line 173, in handle_update
    return self.callback(dispatcher.bot, update, **optional_args)
  File "c:\LearnPython\Lesson2\bot.py", line 28, in planet_user
    planet = user_text[1]
AttributeError: module 'datetime' has no attribute 'strftime'
telegram.ext.dispatcher - ERROR - An uncaught error was raised while processing the update
Traceback (most recent call last):
  File "C:\Users\ito0010\AppData\Local\Programs\Python\Python36\lib\site-packages\telegram\ext\dispatcher.py", line 279, in process_update
    handler.handle_update(update, self)
  File "C:\Users\ito0010\AppData\Local\Programs\Python\Python36\lib\site-packages\telegram\ext\commandhandler.py", line 173, in handle_update
    return self.callback(dispatcher.bot, update, **optional_args)
  File "c:\LearnPython\Lesson2\bot.py", line 29, in planet_user
    today = datetime.strftime(datetime.now(), '%Y/%m/%d')
AttributeError: module 'datetime' has no attribute 'strftime'
telegram.ext.updater - ERROR - Error while getting Updates: Conflict: terminated by other getUpdates request; make sure that only one bot instance is running (409)
telegram.ext.dispatcher - ERROR - No error handlers are registered, logging exception.
Traceback (most recent call last):
  File "C:\Users\ito0010\AppData\Local\Programs\Python\Python36\lib\site-packages\telegram\ext\updater.py", line 319, in _network_loop_retry
    if not action_cb():
  File "C:\Users\ito0010\AppData\Local\Programs\Python\Python36\lib\site-packages\telegram\ext\updater.py", line 280, in polling_action_cb
    allowed_updates=allowed_updates)
  File "C:\Users\ito0010\AppData\Local\Programs\Python\Python36\lib\site-packages\telegram\bot.py", line 65, in decorator
    result = func(self, *args, **kwargs)
  File "C:\Users\ito0010\AppData\Local\Programs\Python\Python36\lib\site-packages\telegram\bot.py", line 1975, in get_updates
    result = self._request.post(url, data, timeout=float(read_latency) + float(timeout))
  File "C:\Users\ito0010\AppData\Local\Programs\Python\Python36\lib\site-packages\telegram\utils\request.py", line 309, in post
    headers={'Content-Type': 'application/json'})
  File "C:\Users\ito0010\AppData\Local\Programs\Python\Python36\lib\site-packages\telegram\utils\request.py", line 233, in _request_wrapper
    raise NetworkError('{0} ({1})'.format(message, resp.status))
telegram.error.NetworkError: Conflict: terminated by other getUpdates request; make sure that only one bot instance is running (409)
telegram.ext.updater - ERROR - Error while getting Updates: Conflict: terminated by other getUpdates request; make sure that only one bot instance is running (409)
telegram.ext.dispatcher - ERROR - No error handlers are registered, logging exception.
Traceback (most recent call last):
  File "C:\Users\ito0010\AppData\Local\Programs\Python\Python36\lib\site-packages\telegram\ext\updater.py", line 319, in _network_loop_retry
    if not action_cb():
  File "C:\Users\ito0010\AppData\Local\Programs\Python\Python36\lib\site-packages\telegram\ext\updater.py", line 280, in polling_action_cb
    allowed_updates=allowed_updates)
  File "C:\Users\ito0010\AppData\Local\Programs\Python\Python36\lib\site-packages\telegram\bot.py", line 65, in decorator
    result = func(self, *args, **kwargs)
  File "C:\Users\ito0010\AppData\Local\Programs\Python\Python36\lib\site-packages\telegram\bot.py", line 1975, in get_updates
    result = self._request.post(url, data, timeout=float(read_latency) + float(timeout))
  File "C:\Users\ito0010\AppData\Local\Programs\Python\Python36\lib\site-packages\telegram\utils\request.py", line 309, in post
    headers={'Content-Type': 'application/json'})
  File "C:\Users\ito0010\AppData\Local\Programs\Python\Python36\lib\site-packages\telegram\utils\request.py", line 233, in _request_wrapper
    raise NetworkError('{0} ({1})'.format(message, resp.status))
telegram.error.NetworkError: Conflict: terminated by other getUpdates request; make sure that only one bot instance is running (409)
telegram.ext.updater - ERROR - Error while getting Updates: Conflict: terminated by other getUpdates request; make sure that only one bot instance is running (409)
telegram.ext.dispatcher - ERROR - No error handlers are registered, logging exception.
Traceback (most recent call last):
  File "C:\Users\ito0010\AppData\Local\Programs\Python\Python36\lib\site-packages\telegram\ext\updater.py", line 319, in _network_loop_retry
    if not action_cb():
  File "C:\Users\ito0010\AppData\Local\Programs\Python\Python36\lib\site-packages\telegram\ext\updater.py", line 280, in polling_action_cb
    allowed_updates=allowed_updates)
  File "C:\Users\ito0010\AppData\Local\Programs\Python\Python36\lib\site-packages\telegram\bot.py", line 65, in decorator
    result = func(self, *args, **kwargs)
  File "C:\Users\ito0010\AppData\Local\Programs\Python\Python36\lib\site-packages\telegram\bot.py", line 1975, in get_updates
    result = self._request.post(url, data, timeout=float(read_latency) + float(timeout))
  File "C:\Users\ito0010\AppData\Local\Programs\Python\Python36\lib\site-packages\telegram\utils\request.py", line 309, in post
    headers={'Content-Type': 'application/json'})
  File "C:\Users\ito0010\AppData\Local\Programs\Python\Python36\lib\site-packages\telegram\utils\request.py", line 233, in _request_wrapper
    raise NetworkError('{0} ({1})'.format(message, resp.status))
telegram.error.NetworkError: Conflict: terminated by other getUpdates request; make sure that only one bot instance is running (409)
telegram.ext.updater - ERROR - Error while getting Updates: Conflict: terminated by other getUpdates request; make sure that only one bot instance is running (409)
telegram.ext.dispatcher - ERROR - No error handlers are registered, logging exception.
Traceback (most recent call last):
  File "C:\Users\ito0010\AppData\Local\Programs\Python\Python36\lib\site-packages\telegram\ext\updater.py", line 319, in _network_loop_retry
    if not action_cb():
  File "C:\Users\ito0010\AppData\Local\Programs\Python\Python36\lib\site-packages\telegram\ext\updater.py", line 280, in polling_action_cb
    allowed_updates=allowed_updates)
  File "C:\Users\ito0010\AppData\Local\Programs\Python\Python36\lib\site-packages\telegram\bot.py", line 65, in decorator
    result = func(self, *args, **kwargs)
  File "C:\Users\ito0010\AppData\Local\Programs\Python\Python36\lib\site-packages\telegram\bot.py", line 1975, in get_updates
    result = self._request.post(url, data, timeout=float(read_latency) + float(timeout))
  File "C:\Users\ito0010\AppData\Local\Programs\Python\Python36\lib\site-packages\telegram\utils\request.py", line 309, in post
    headers={'Content-Type': 'application/json'})
  File "C:\Users\ito0010\AppData\Local\Programs\Python\Python36\lib\site-packages\telegram\utils\request.py", line 233, in _request_wrapper
    raise NetworkError('{0} ({1})'.format(message, resp.status))
telegram.error.NetworkError: Conflict: terminated by other getUpdates request; make sure that only one bot instance is running (409)
telegram.ext.updater - ERROR - Error while getting Updates: Conflict: terminated by other getUpdates request; make sure that only one bot instance is running (409)
telegram.ext.dispatcher - ERROR - No error handlers are registered, logging exception.
Traceback (most recent call last):
  File "C:\Users\ito0010\AppData\Local\Programs\Python\Python36\lib\site-packages\telegram\ext\updater.py", line 319, in _network_loop_retry
    if not action_cb():
  File "C:\Users\ito0010\AppData\Local\Programs\Python\Python36\lib\site-packages\telegram\ext\updater.py", line 280, in polling_action_cb
    allowed_updates=allowed_updates)
  File "C:\Users\ito0010\AppData\Local\Programs\Python\Python36\lib\site-packages\telegram\bot.py", line 65, in decorator
    result = func(self, *args, **kwargs)
  File "C:\Users\ito0010\AppData\Local\Programs\Python\Python36\lib\site-packages\telegram\bot.py", line 1975, in get_updates
    result = self._request.post(url, data, timeout=float(read_latency) + float(timeout))
  File "C:\Users\ito0010\AppData\Local\Programs\Python\Python36\lib\site-packages\telegram\utils\request.py", line 309, in post
    headers={'Content-Type': 'application/json'})
  File "C:\Users\ito0010\AppData\Local\Programs\Python\Python36\lib\site-packages\telegram\utils\request.py", line 233, in _request_wrapper
    raise NetworkError('{0} ({1})'.format(message, resp.status))
telegram.error.NetworkError: Conflict: terminated by other getUpdates request; make sure that only one bot instance is running (409)
telegram.ext.updater - ERROR - Error while getting Updates: Conflict: terminated by other getUpdates request; make sure that only one bot instance is running (409)
telegram.ext.dispatcher - ERROR - No error handlers are registered, logging exception.
Traceback (most recent call last):
  File "C:\Users\ito0010\AppData\Local\Programs\Python\Python36\lib\site-packages\telegram\ext\updater.py", line 319, in _network_loop_retry
    if not action_cb():
  File "C:\Users\ito0010\AppData\Local\Programs\Python\Python36\lib\site-packages\telegram\ext\updater.py", line 280, in polling_action_cb
    allowed_updates=allowed_updates)
  File "C:\Users\ito0010\AppData\Local\Programs\Python\Python36\lib\site-packages\telegram\bot.py", line 65, in decorator
    result = func(self, *args, **kwargs)
  File "C:\Users\ito0010\AppData\Local\Programs\Python\Python36\lib\site-packages\telegram\bot.py", line 1975, in get_updates
    result = self._request.post(url, data, timeout=float(read_latency) + float(timeout))
  File "C:\Users\ito0010\AppData\Local\Programs\Python\Python36\lib\site-packages\telegram\utils\request.py", line 309, in post
    headers={'Content-Type': 'application/json'})
  File "C:\Users\ito0010\AppData\Local\Programs\Python\Python36\lib\site-packages\telegram\utils\request.py", line 233, in _request_wrapper
    raise NetworkError('{0} ({1})'.format(message, resp.status))
telegram.error.NetworkError: Conflict: terminated by other getUpdates request; make sure that only one bot instance is running (409)
telegram.ext.dispatcher - ERROR - An uncaught error was raised while processing the update
Traceback (most recent call last):
  File "C:\Users\ito0010\AppData\Local\Programs\Python\Python36\lib\site-packages\telegram\ext\dispatcher.py", line 279, in process_update
    handler.handle_update(update, self)
  File "C:\Users\ito0010\AppData\Local\Programs\Python\Python36\lib\site-packages\telegram\ext\commandhandler.py", line 173, in handle_update
    return self.callback(dispatcher.bot, update, **optional_args)
  File "c:\LearnPython\Lesson2\bot.py", line 28, in planet_user
    planet = user_text[1]
AttributeError: module 'datetime' has no attribute 'strftime'
telegram.ext.dispatcher - ERROR - An uncaught error was raised while processing the update
Traceback (most recent call last):
  File "C:\Users\ito0010\AppData\Local\Programs\Python\Python36\lib\site-packages\telegram\ext\dispatcher.py", line 279, in process_update
    handler.handle_update(update, self)
  File "C:\Users\ito0010\AppData\Local\Programs\Python\Python36\lib\site-packages\telegram\ext\commandhandler.py", line 173, in handle_update
    return self.callback(dispatcher.bot, update, **optional_args)
  File "c:\LearnPython\Lesson2\bot.py", line 29, in planet_user
    today = datetime.strftime(datetime.now(), '%Y/%m/%d')
AttributeError: module 'datetime' has no attribute 'strftime'
telegram.ext.updater - ERROR - Error while getting Updates: Conflict: terminated by other getUpdates request; make sure that only one bot instance is running (409)
telegram.ext.dispatcher - ERROR - No error handlers are registered, logging exception.
Traceback (most recent call last):
  File "C:\Users\ito0010\AppData\Local\Programs\Python\Python36\lib\site-packages\telegram\ext\updater.py", line 319, in _network_loop_retry
    if not action_cb():
  File "C:\Users\ito0010\AppData\Local\Programs\Python\Python36\lib\site-packages\telegram\ext\updater.py", line 280, in polling_action_cb
    allowed_updates=allowed_updates)
  File "C:\Users\ito0010\AppData\Local\Programs\Python\Python36\lib\site-packages\telegram\bot.py", line 65, in decorator
    result = func(self, *args, **kwargs)
  File "C:\Users\ito0010\AppData\Local\Programs\Python\Python36\lib\site-packages\telegram\bot.py", line 1975, in get_updates
    result = self._request.post(url, data, timeout=float(read_latency) + float(timeout))
  File "C:\Users\ito0010\AppData\Local\Programs\Python\Python36\lib\site-packages\telegram\utils\request.py", line 309, in post
    headers={'Content-Type': 'application/json'})
  File "C:\Users\ito0010\AppData\Local\Programs\Python\Python36\lib\site-packages\telegram\utils\request.py", line 233, in _request_wrapper
    raise NetworkError('{0} ({1})'.format(message, resp.status))
telegram.error.NetworkError: Conflict: terminated by other getUpdates request; make sure that only one bot instance is running (409)
telegram.ext.updater - ERROR - Error while getting Updates: Conflict: terminated by other getUpdates request; make sure that only one bot instance is running (409)
telegram.ext.dispatcher - ERROR - No error handlers are registered, logging exception.
Traceback (most recent call last):
  File "C:\Users\ito0010\AppData\Local\Programs\Python\Python36\lib\site-packages\telegram\ext\updater.py", line 319, in _network_loop_retry
    if not action_cb():
  File "C:\Users\ito0010\AppData\Local\Programs\Python\Python36\lib\site-packages\telegram\ext\updater.py", line 280, in polling_action_cb
    allowed_updates=allowed_updates)
  File "C:\Users\ito0010\AppData\Local\Programs\Python\Python36\lib\site-packages\telegram\bot.py", line 65, in decorator
    result = func(self, *args, **kwargs)
  File "C:\Users\ito0010\AppData\Local\Programs\Python\Python36\lib\site-packages\telegram\bot.py", line 1975, in get_updates
    result = self._request.post(url, data, timeout=float(read_latency) + float(timeout))
  File "C:\Users\ito0010\AppData\Local\Programs\Python\Python36\lib\site-packages\telegram\utils\request.py", line 309, in post
    headers={'Content-Type': 'application/json'})
  File "C:\Users\ito0010\AppData\Local\Programs\Python\Python36\lib\site-packages\telegram\utils\request.py", line 233, in _request_wrapper
    raise NetworkError('{0} ({1})'.format(message, resp.status))
telegram.error.NetworkError: Conflict: terminated by other getUpdates request; make sure that only one bot instance is running (409)
telegram.ext.updater - ERROR - Error while getting Updates: Conflict: terminated by other getUpdates request; make sure that only one bot instance is running (409)
telegram.ext.dispatcher - ERROR - No error handlers are registered, logging exception.
Traceback (most recent call last):
  File "C:\Users\ito0010\AppData\Local\Programs\Python\Python36\lib\site-packages\telegram\ext\updater.py", line 319, in _network_loop_retry
    if not action_cb():
  File "C:\Users\ito0010\AppData\Local\Programs\Python\Python36\lib\site-packages\telegram\ext\updater.py", line 280, in polling_action_cb
    allowed_updates=allowed_updates)
  File "C:\Users\ito0010\AppData\Local\Programs\Python\Python36\lib\site-packages\telegram\bot.py", line 65, in decorator
    result = func(self, *args, **kwargs)
  File "C:\Users\ito0010\AppData\Local\Programs\Python\Python36\lib\site-packages\telegram\bot.py", line 1975, in get_updates
    result = self._request.post(url, data, timeout=float(read_latency) + float(timeout))
  File "C:\Users\ito0010\AppData\Local\Programs\Python\Python36\lib\site-packages\telegram\utils\request.py", line 309, in post
    headers={'Content-Type': 'application/json'})
  File "C:\Users\ito0010\AppData\Local\Programs\Python\Python36\lib\site-packages\telegram\utils\request.py", line 233, in _request_wrapper
    raise NetworkError('{0} ({1})'.format(message, resp.status))
telegram.error.NetworkError: Conflict: terminated by other getUpdates request; make sure that only one bot instance is running (409)
telegram.ext.updater - INFO - Received signal 2 (SIGINT), stopping...
telegram.ext.updater - WARNING - Exiting immediately!
telegram.ext.updater - ERROR - Error while getting Updates: Conflict: terminated by other getUpdates request; make sure that only one bot instance is running (409)
telegram.ext.dispatcher - ERROR - No error handlers are registered, logging exception.
Traceback (most recent call last):
  File "C:\Users\ito0010\AppData\Local\Programs\Python\Python36\lib\site-packages\telegram\ext\updater.py", line 319, in _network_loop_retry
    if not action_cb():
  File "C:\Users\ito0010\AppData\Local\Programs\Python\Python36\lib\site-packages\telegram\ext\updater.py", line 280, in polling_action_cb
    allowed_updates=allowed_updates)
  File "C:\Users\ito0010\AppData\Local\Programs\Python\Python36\lib\site-packages\telegram\bot.py", line 65, in decorator
    result = func(self, *args, **kwargs)
  File "C:\Users\ito0010\AppData\Local\Programs\Python\Python36\lib\site-packages\telegram\bot.py", line 1975, in get_updates
    result = self._request.post(url, data, timeout=float(read_latency) + float(timeout))
  File "C:\Users\ito0010\AppData\Local\Programs\Python\Python36\lib\site-packages\telegram\utils\request.py", line 309, in post
    headers={'Content-Type': 'application/json'})
  File "C:\Users\ito0010\AppData\Local\Programs\Python\Python36\lib\site-packages\telegram\utils\request.py", line 233, in _request_wrapper
    raise NetworkError('{0} ({1})'.format(message, resp.status))
telegram.error.NetworkError: Conflict: terminated by other getUpdates request; make sure that only one bot instance is running (409)
telegram.ext.dispatcher - ERROR - An uncaught error was raised while processing the update
Traceback (most recent call last):
  File "C:\Users\ito0010\AppData\Local\Programs\Python\Python36\lib\site-packages\telegram\ext\dispatcher.py", line 279, in process_update
    handler.handle_update(update, self)
  File "C:\Users\ito0010\AppData\Local\Programs\Python\Python36\lib\site-packages\telegram\ext\commandhandler.py", line 173, in handle_update
    return self.callback(dispatcher.bot, update, **optional_args)
  File "c:\LearnPython\Lesson2\bot.py", line 28, in planet_user
    print(planet)
AttributeError: module 'datetime' has no attribute 'strftime'
telegram.ext.updater - ERROR - Error while getting Updates: Conflict: terminated by other getUpdates request; make sure that only one bot instance is running (409)
telegram.ext.dispatcher - ERROR - An uncaught error was raised while processing the update
Traceback (most recent call last):
  File "C:\Users\ito0010\AppData\Local\Programs\Python\Python36\lib\site-packages\telegram\ext\dispatcher.py", line 279, in process_update
    handler.handle_update(update, self)
  File "C:\Users\ito0010\AppData\Local\Programs\Python\Python36\lib\site-packages\telegram\ext\commandhandler.py", line 173, in handle_update
    return self.callback(dispatcher.bot, update, **optional_args)
  File "c:\LearnPython\Lesson2\bot.py", line 29, in planet_user
    today = datetime.strftime(datetime.now(), '%Y/%m/%d')
AttributeError: module 'datetime' has no attribute 'strftime'
telegram.ext.dispatcher - ERROR - No error handlers are registered, logging exception.
Traceback (most recent call last):
  File "C:\Users\ito0010\AppData\Local\Programs\Python\Python36\lib\site-packages\telegram\ext\updater.py", line 319, in _network_loop_retry
    if not action_cb():
  File "C:\Users\ito0010\AppData\Local\Programs\Python\Python36\lib\site-packages\telegram\ext\updater.py", line 280, in polling_action_cb
    allowed_updates=allowed_updates)
  File "C:\Users\ito0010\AppData\Local\Programs\Python\Python36\lib\site-packages\telegram\bot.py", line 65, in decorator
    result = func(self, *args, **kwargs)
  File "C:\Users\ito0010\AppData\Local\Programs\Python\Python36\lib\site-packages\telegram\bot.py", line 1975, in get_updates
    result = self._request.post(url, data, timeout=float(read_latency) + float(timeout))
  File "C:\Users\ito0010\AppData\Local\Programs\Python\Python36\lib\site-packages\telegram\utils\request.py", line 309, in post
    headers={'Content-Type': 'application/json'})
  File "C:\Users\ito0010\AppData\Local\Programs\Python\Python36\lib\site-packages\telegram\utils\request.py", line 233, in _request_wrapper
    raise NetworkError('{0} ({1})'.format(message, resp.status))
telegram.error.NetworkError: Conflict: terminated by other getUpdates request; make sure that only one bot instance is running (409)
telegram.ext.updater - ERROR - Error while getting Updates: Conflict: terminated by other getUpdates request; make sure that only one bot instance is running (409)
telegram.ext.dispatcher - ERROR - No error handlers are registered, logging exception.
Traceback (most recent call last):
  File "C:\Users\ito0010\AppData\Local\Programs\Python\Python36\lib\site-packages\telegram\ext\updater.py", line 319, in _network_loop_retry
    if not action_cb():
  File "C:\Users\ito0010\AppData\Local\Programs\Python\Python36\lib\site-packages\telegram\ext\updater.py", line 280, in polling_action_cb
    allowed_updates=allowed_updates)
  File "C:\Users\ito0010\AppData\Local\Programs\Python\Python36\lib\site-packages\telegram\bot.py", line 65, in decorator
    result = func(self, *args, **kwargs)
  File "C:\Users\ito0010\AppData\Local\Programs\Python\Python36\lib\site-packages\telegram\bot.py", line 1975, in get_updates
    result = self._request.post(url, data, timeout=float(read_latency) + float(timeout))
  File "C:\Users\ito0010\AppData\Local\Programs\Python\Python36\lib\site-packages\telegram\utils\request.py", line 309, in post
    headers={'Content-Type': 'application/json'})
  File "C:\Users\ito0010\AppData\Local\Programs\Python\Python36\lib\site-packages\telegram\utils\request.py", line 233, in _request_wrapper
    raise NetworkError('{0} ({1})'.format(message, resp.status))
telegram.error.NetworkError: Conflict: terminated by other getUpdates request; make sure that only one bot instance is running (409)
telegram.ext.updater - ERROR - Error while getting Updates: Conflict: terminated by other getUpdates request; make sure that only one bot instance is running (409)
telegram.ext.dispatcher - ERROR - No error handlers are registered, logging exception.
Traceback (most recent call last):
  File "C:\Users\ito0010\AppData\Local\Programs\Python\Python36\lib\site-packages\telegram\ext\updater.py", line 319, in _network_loop_retry
    if not action_cb():
  File "C:\Users\ito0010\AppData\Local\Programs\Python\Python36\lib\site-packages\telegram\ext\updater.py", line 280, in polling_action_cb
    allowed_updates=allowed_updates)
  File "C:\Users\ito0010\AppData\Local\Programs\Python\Python36\lib\site-packages\telegram\bot.py", line 65, in decorator
    result = func(self, *args, **kwargs)
  File "C:\Users\ito0010\AppData\Local\Programs\Python\Python36\lib\site-packages\telegram\bot.py", line 1975, in get_updates
    result = self._request.post(url, data, timeout=float(read_latency) + float(timeout))
  File "C:\Users\ito0010\AppData\Local\Programs\Python\Python36\lib\site-packages\telegram\utils\request.py", line 309, in post
    headers={'Content-Type': 'application/json'})
  File "C:\Users\ito0010\AppData\Local\Programs\Python\Python36\lib\site-packages\telegram\utils\request.py", line 233, in _request_wrapper
    raise NetworkError('{0} ({1})'.format(message, resp.status))
telegram.error.NetworkError: Conflict: terminated by other getUpdates request; make sure that only one bot instance is running (409)
telegram.ext.updater - ERROR - Error while getting Updates: Conflict: terminated by other getUpdates request; make sure that only one bot instance is running (409)
telegram.ext.dispatcher - ERROR - No error handlers are registered, logging exception.
Traceback (most recent call last):
  File "C:\Users\ito0010\AppData\Local\Programs\Python\Python36\lib\site-packages\telegram\ext\updater.py", line 319, in _network_loop_retry
    if not action_cb():
  File "C:\Users\ito0010\AppData\Local\Programs\Python\Python36\lib\site-packages\telegram\ext\updater.py", line 280, in polling_action_cb
    allowed_updates=allowed_updates)
  File "C:\Users\ito0010\AppData\Local\Programs\Python\Python36\lib\site-packages\telegram\bot.py", line 65, in decorator
    result = func(self, *args, **kwargs)
  File "C:\Users\ito0010\AppData\Local\Programs\Python\Python36\lib\site-packages\telegram\bot.py", line 1975, in get_updates
    result = self._request.post(url, data, timeout=float(read_latency) + float(timeout))
  File "C:\Users\ito0010\AppData\Local\Programs\Python\Python36\lib\site-packages\telegram\utils\request.py", line 309, in post
    headers={'Content-Type': 'application/json'})
  File "C:\Users\ito0010\AppData\Local\Programs\Python\Python36\lib\site-packages\telegram\utils\request.py", line 233, in _request_wrapper
    raise NetworkError('{0} ({1})'.format(message, resp.status))
telegram.error.NetworkError: Conflict: terminated by other getUpdates request; make sure that only one bot instance is running (409)
telegram.ext.updater - ERROR - Error while getting Updates: Conflict: terminated by other getUpdates request; make sure that only one bot instance is running (409)
telegram.ext.dispatcher - ERROR - No error handlers are registered, logging exception.
Traceback (most recent call last):
  File "C:\Users\ito0010\AppData\Local\Programs\Python\Python36\lib\site-packages\telegram\ext\updater.py", line 319, in _network_loop_retry
    if not action_cb():
  File "C:\Users\ito0010\AppData\Local\Programs\Python\Python36\lib\site-packages\telegram\ext\updater.py", line 280, in polling_action_cb
    allowed_updates=allowed_updates)
  File "C:\Users\ito0010\AppData\Local\Programs\Python\Python36\lib\site-packages\telegram\bot.py", line 65, in decorator
    result = func(self, *args, **kwargs)
  File "C:\Users\ito0010\AppData\Local\Programs\Python\Python36\lib\site-packages\telegram\bot.py", line 1975, in get_updates
    result = self._request.post(url, data, timeout=float(read_latency) + float(timeout))
  File "C:\Users\ito0010\AppData\Local\Programs\Python\Python36\lib\site-packages\telegram\utils\request.py", line 309, in post
    headers={'Content-Type': 'application/json'})
  File "C:\Users\ito0010\AppData\Local\Programs\Python\Python36\lib\site-packages\telegram\utils\request.py", line 233, in _request_wrapper
    raise NetworkError('{0} ({1})'.format(message, resp.status))
telegram.error.NetworkError: Conflict: terminated by other getUpdates request; make sure that only one bot instance is running (409)
telegram.ext.updater - ERROR - Error while getting Updates: Conflict: terminated by other getUpdates request; make sure that only one bot instance is running (409)
telegram.ext.dispatcher - ERROR - No error handlers are registered, logging exception.
Traceback (most recent call last):
  File "C:\Users\ito0010\AppData\Local\Programs\Python\Python36\lib\site-packages\telegram\ext\updater.py", line 319, in _network_loop_retry
    if not action_cb():
  File "C:\Users\ito0010\AppData\Local\Programs\Python\Python36\lib\site-packages\telegram\ext\updater.py", line 280, in polling_action_cb
    allowed_updates=allowed_updates)
  File "C:\Users\ito0010\AppData\Local\Programs\Python\Python36\lib\site-packages\telegram\bot.py", line 65, in decorator
    result = func(self, *args, **kwargs)
  File "C:\Users\ito0010\AppData\Local\Programs\Python\Python36\lib\site-packages\telegram\bot.py", line 1975, in get_updates
    result = self._request.post(url, data, timeout=float(read_latency) + float(timeout))
  File "C:\Users\ito0010\AppData\Local\Programs\Python\Python36\lib\site-packages\telegram\utils\request.py", line 309, in post
    headers={'Content-Type': 'application/json'})
  File "C:\Users\ito0010\AppData\Local\Programs\Python\Python36\lib\site-packages\telegram\utils\request.py", line 233, in _request_wrapper
    raise NetworkError('{0} ({1})'.format(message, resp.status))
telegram.error.NetworkError: Conflict: terminated by other getUpdates request; make sure that only one bot instance is running (409)
telegram.ext.updater - ERROR - Error while getting Updates: Conflict: terminated by other getUpdates request; make sure that only one bot instance is running (409)
telegram.ext.dispatcher - ERROR - No error handlers are registered, logging exception.
Traceback (most recent call last):
  File "C:\Users\ito0010\AppData\Local\Programs\Python\Python36\lib\site-packages\telegram\ext\updater.py", line 319, in _network_loop_retry
    if not action_cb():
  File "C:\Users\ito0010\AppData\Local\Programs\Python\Python36\lib\site-packages\telegram\ext\updater.py", line 280, in polling_action_cb
    allowed_updates=allowed_updates)
  File "C:\Users\ito0010\AppData\Local\Programs\Python\Python36\lib\site-packages\telegram\bot.py", line 65, in decorator
    result = func(self, *args, **kwargs)
  File "C:\Users\ito0010\AppData\Local\Programs\Python\Python36\lib\site-packages\telegram\bot.py", line 1975, in get_updates
    result = self._request.post(url, data, timeout=float(read_latency) + float(timeout))
  File "C:\Users\ito0010\AppData\Local\Programs\Python\Python36\lib\site-packages\telegram\utils\request.py", line 309, in post
    headers={'Content-Type': 'application/json'})
  File "C:\Users\ito0010\AppData\Local\Programs\Python\Python36\lib\site-packages\telegram\utils\request.py", line 233, in _request_wrapper
    raise NetworkError('{0} ({1})'.format(message, resp.status))
telegram.error.NetworkError: Conflict: terminated by other getUpdates request; make sure that only one bot instance is running (409)
telegram.ext.updater - ERROR - Error while getting Updates: Conflict: terminated by other getUpdates request; make sure that only one bot instance is running (409)
telegram.ext.dispatcher - ERROR - No error handlers are registered, logging exception.
Traceback (most recent call last):
  File "C:\Users\ito0010\AppData\Local\Programs\Python\Python36\lib\site-packages\telegram\ext\updater.py", line 319, in _network_loop_retry
    if not action_cb():
  File "C:\Users\ito0010\AppData\Local\Programs\Python\Python36\lib\site-packages\telegram\ext\updater.py", line 280, in polling_action_cb
    allowed_updates=allowed_updates)
  File "C:\Users\ito0010\AppData\Local\Programs\Python\Python36\lib\site-packages\telegram\bot.py", line 65, in decorator
    result = func(self, *args, **kwargs)
  File "C:\Users\ito0010\AppData\Local\Programs\Python\Python36\lib\site-packages\telegram\bot.py", line 1975, in get_updates
    result = self._request.post(url, data, timeout=float(read_latency) + float(timeout))
  File "C:\Users\ito0010\AppData\Local\Programs\Python\Python36\lib\site-packages\telegram\utils\request.py", line 309, in post
    headers={'Content-Type': 'application/json'})
  File "C:\Users\ito0010\AppData\Local\Programs\Python\Python36\lib\site-packages\telegram\utils\request.py", line 233, in _request_wrapper
    raise NetworkError('{0} ({1})'.format(message, resp.status))
telegram.error.NetworkError: Conflict: terminated by other getUpdates request; make sure that only one bot instance is running (409)
telegram.ext.updater - ERROR - Error while getting Updates: Conflict: terminated by other getUpdates request; make sure that only one bot instance is running (409)
telegram.ext.dispatcher - ERROR - No error handlers are registered, logging exception.
Traceback (most recent call last):
  File "C:\Users\ito0010\AppData\Local\Programs\Python\Python36\lib\site-packages\telegram\ext\updater.py", line 319, in _network_loop_retry
    if not action_cb():
  File "C:\Users\ito0010\AppData\Local\Programs\Python\Python36\lib\site-packages\telegram\ext\updater.py", line 280, in polling_action_cb
    allowed_updates=allowed_updates)
  File "C:\Users\ito0010\AppData\Local\Programs\Python\Python36\lib\site-packages\telegram\bot.py", line 65, in decorator
    result = func(self, *args, **kwargs)
  File "C:\Users\ito0010\AppData\Local\Programs\Python\Python36\lib\site-packages\telegram\bot.py", line 1975, in get_updates
    result = self._request.post(url, data, timeout=float(read_latency) + float(timeout))
  File "C:\Users\ito0010\AppData\Local\Programs\Python\Python36\lib\site-packages\telegram\utils\request.py", line 309, in post
    headers={'Content-Type': 'application/json'})
  File "C:\Users\ito0010\AppData\Local\Programs\Python\Python36\lib\site-packages\telegram\utils\request.py", line 233, in _request_wrapper
    raise NetworkError('{0} ({1})'.format(message, resp.status))
telegram.error.NetworkError: Conflict: terminated by other getUpdates request; make sure that only one bot instance is running (409)
telegram.ext.updater - ERROR - Error while getting Updates: Conflict: terminated by other getUpdates request; make sure that only one bot instance is running (409)
telegram.ext.dispatcher - ERROR - No error handlers are registered, logging exception.
Traceback (most recent call last):
  File "C:\Users\ito0010\AppData\Local\Programs\Python\Python36\lib\site-packages\telegram\ext\updater.py", line 319, in _network_loop_retry
    if not action_cb():
  File "C:\Users\ito0010\AppData\Local\Programs\Python\Python36\lib\site-packages\telegram\ext\updater.py", line 280, in polling_action_cb
    allowed_updates=allowed_updates)
  File "C:\Users\ito0010\AppData\Local\Programs\Python\Python36\lib\site-packages\telegram\bot.py", line 65, in decorator
    result = func(self, *args, **kwargs)
  File "C:\Users\ito0010\AppData\Local\Programs\Python\Python36\lib\site-packages\telegram\bot.py", line 1975, in get_updates
    result = self._request.post(url, data, timeout=float(read_latency) + float(timeout))
  File "C:\Users\ito0010\AppData\Local\Programs\Python\Python36\lib\site-packages\telegram\utils\request.py", line 309, in post
    headers={'Content-Type': 'application/json'})
  File "C:\Users\ito0010\AppData\Local\Programs\Python\Python36\lib\site-packages\telegram\utils\request.py", line 233, in _request_wrapper
    raise NetworkError('{0} ({1})'.format(message, resp.status))
telegram.error.NetworkError: Conflict: terminated by other getUpdates request; make sure that only one bot instance is running (409)
telegram.ext.updater - ERROR - Error while getting Updates: Conflict: terminated by other getUpdates request; make sure that only one bot instance is running (409)
telegram.ext.dispatcher - ERROR - No error handlers are registered, logging exception.
Traceback (most recent call last):
  File "C:\Users\ito0010\AppData\Local\Programs\Python\Python36\lib\site-packages\telegram\ext\updater.py", line 319, in _network_loop_retry
    if not action_cb():
  File "C:\Users\ito0010\AppData\Local\Programs\Python\Python36\lib\site-packages\telegram\ext\updater.py", line 280, in polling_action_cb
    allowed_updates=allowed_updates)
  File "C:\Users\ito0010\AppData\Local\Programs\Python\Python36\lib\site-packages\telegram\bot.py", line 65, in decorator
    result = func(self, *args, **kwargs)
  File "C:\Users\ito0010\AppData\Local\Programs\Python\Python36\lib\site-packages\telegram\bot.py", line 1975, in get_updates
    result = self._request.post(url, data, timeout=float(read_latency) + float(timeout))
  File "C:\Users\ito0010\AppData\Local\Programs\Python\Python36\lib\site-packages\telegram\utils\request.py", line 309, in post
    headers={'Content-Type': 'application/json'})
  File "C:\Users\ito0010\AppData\Local\Programs\Python\Python36\lib\site-packages\telegram\utils\request.py", line 233, in _request_wrapper
    raise NetworkError('{0} ({1})'.format(message, resp.status))
telegram.error.NetworkError: Conflict: terminated by other getUpdates request; make sure that only one bot instance is running (409)
telegram.ext.updater - ERROR - Error while getting Updates: Conflict: terminated by other getUpdates request; make sure that only one bot instance is running (409)
telegram.ext.dispatcher - ERROR - No error handlers are registered, logging exception.
Traceback (most recent call last):
  File "C:\Users\ito0010\AppData\Local\Programs\Python\Python36\lib\site-packages\telegram\ext\updater.py", line 319, in _network_loop_retry
    if not action_cb():
  File "C:\Users\ito0010\AppData\Local\Programs\Python\Python36\lib\site-packages\telegram\ext\updater.py", line 280, in polling_action_cb
    allowed_updates=allowed_updates)
  File "C:\Users\ito0010\AppData\Local\Programs\Python\Python36\lib\site-packages\telegram\bot.py", line 65, in decorator
    result = func(self, *args, **kwargs)
  File "C:\Users\ito0010\AppData\Local\Programs\Python\Python36\lib\site-packages\telegram\bot.py", line 1975, in get_updates
    result = self._request.post(url, data, timeout=float(read_latency) + float(timeout))
  File "C:\Users\ito0010\AppData\Local\Programs\Python\Python36\lib\site-packages\telegram\utils\request.py", line 309, in post
    headers={'Content-Type': 'application/json'})
  File "C:\Users\ito0010\AppData\Local\Programs\Python\Python36\lib\site-packages\telegram\utils\request.py", line 233, in _request_wrapper
    raise NetworkError('{0} ({1})'.format(message, resp.status))
telegram.error.NetworkError: Conflict: terminated by other getUpdates request; make sure that only one bot instance is running (409)
telegram.ext.updater - ERROR - Error while getting Updates: Conflict: terminated by other getUpdates request; make sure that only one bot instance is running (409)
telegram.ext.dispatcher - ERROR - No error handlers are registered, logging exception.
Traceback (most recent call last):
  File "C:\Users\ito0010\AppData\Local\Programs\Python\Python36\lib\site-packages\telegram\ext\updater.py", line 319, in _network_loop_retry
    if not action_cb():
  File "C:\Users\ito0010\AppData\Local\Programs\Python\Python36\lib\site-packages\telegram\ext\updater.py", line 280, in polling_action_cb
    allowed_updates=allowed_updates)
  File "C:\Users\ito0010\AppData\Local\Programs\Python\Python36\lib\site-packages\telegram\bot.py", line 65, in decorator
    result = func(self, *args, **kwargs)
  File "C:\Users\ito0010\AppData\Local\Programs\Python\Python36\lib\site-packages\telegram\bot.py", line 1975, in get_updates
    result = self._request.post(url, data, timeout=float(read_latency) + float(timeout))
  File "C:\Users\ito0010\AppData\Local\Programs\Python\Python36\lib\site-packages\telegram\utils\request.py", line 309, in post
    headers={'Content-Type': 'application/json'})
  File "C:\Users\ito0010\AppData\Local\Programs\Python\Python36\lib\site-packages\telegram\utils\request.py", line 233, in _request_wrapper
    raise NetworkError('{0} ({1})'.format(message, resp.status))
telegram.error.NetworkError: Conflict: terminated by other getUpdates request; make sure that only one bot instance is running (409)
telegram.ext.updater - ERROR - Error while getting Updates: Conflict: terminated by other getUpdates request; make sure that only one bot instance is running (409)
telegram.ext.dispatcher - ERROR - No error handlers are registered, logging exception.
Traceback (most recent call last):
  File "C:\Users\ito0010\AppData\Local\Programs\Python\Python36\lib\site-packages\telegram\ext\updater.py", line 319, in _network_loop_retry
    if not action_cb():
  File "C:\Users\ito0010\AppData\Local\Programs\Python\Python36\lib\site-packages\telegram\ext\updater.py", line 280, in polling_action_cb
    allowed_updates=allowed_updates)
  File "C:\Users\ito0010\AppData\Local\Programs\Python\Python36\lib\site-packages\telegram\bot.py", line 65, in decorator
    result = func(self, *args, **kwargs)
  File "C:\Users\ito0010\AppData\Local\Programs\Python\Python36\lib\site-packages\telegram\bot.py", line 1975, in get_updates
    result = self._request.post(url, data, timeout=float(read_latency) + float(timeout))
  File "C:\Users\ito0010\AppData\Local\Programs\Python\Python36\lib\site-packages\telegram\utils\request.py", line 309, in post
    headers={'Content-Type': 'application/json'})
  File "C:\Users\ito0010\AppData\Local\Programs\Python\Python36\lib\site-packages\telegram\utils\request.py", line 233, in _request_wrapper
    raise NetworkError('{0} ({1})'.format(message, resp.status))
telegram.error.NetworkError: Conflict: terminated by other getUpdates request; make sure that only one bot instance is running (409)
telegram.ext.updater - INFO - Received signal 2 (SIGINT), stopping...
telegram.ext.updater - WARNING - Exiting immediately!
telegram.ext.updater - ERROR - Error while getting Updates: Conflict: terminated by other getUpdates request; make sure that only one bot instance is running (409)
telegram.ext.dispatcher - ERROR - No error handlers are registered, logging exception.
Traceback (most recent call last):
  File "C:\Users\ito0010\AppData\Local\Programs\Python\Python36\lib\site-packages\telegram\ext\updater.py", line 319, in _network_loop_retry
    if not action_cb():
  File "C:\Users\ito0010\AppData\Local\Programs\Python\Python36\lib\site-packages\telegram\ext\updater.py", line 280, in polling_action_cb
    allowed_updates=allowed_updates)
  File "C:\Users\ito0010\AppData\Local\Programs\Python\Python36\lib\site-packages\telegram\bot.py", line 65, in decorator
    result = func(self, *args, **kwargs)
  File "C:\Users\ito0010\AppData\Local\Programs\Python\Python36\lib\site-packages\telegram\bot.py", line 1975, in get_updates
    result = self._request.post(url, data, timeout=float(read_latency) + float(timeout))
  File "C:\Users\ito0010\AppData\Local\Programs\Python\Python36\lib\site-packages\telegram\utils\request.py", line 309, in post
    headers={'Content-Type': 'application/json'})
  File "C:\Users\ito0010\AppData\Local\Programs\Python\Python36\lib\site-packages\telegram\utils\request.py", line 233, in _request_wrapper
    raise NetworkError('{0} ({1})'.format(message, resp.status))
telegram.error.NetworkError: Conflict: terminated by other getUpdates request; make sure that only one bot instance is running (409)
telegram.ext.dispatcher - ERROR - An uncaught error was raised while processing the update
Traceback (most recent call last):
  File "C:\Users\ito0010\AppData\Local\Programs\Python\Python36\lib\site-packages\telegram\ext\dispatcher.py", line 279, in process_update
    handler.handle_update(update, self)
  File "C:\Users\ito0010\AppData\Local\Programs\Python\Python36\lib\site-packages\telegram\ext\commandhandler.py", line 173, in handle_update
    return self.callback(dispatcher.bot, update, **optional_args)
  File "c:\LearnPython\Lesson2\bot.py", line 29, in planet_user
    today = datetime.strftime(datetime.now(), '%Y/%m/%d')
AttributeError: module 'datetime' has no attribute 'strftime'
telegram.ext.updater - ERROR - Error while getting Updates: Conflict: terminated by other getUpdates request; make sure that only one bot instance is running (409)
telegram.ext.dispatcher - ERROR - No error handlers are registered, logging exception.
Traceback (most recent call last):
  File "C:\Users\ito0010\AppData\Local\Programs\Python\Python36\lib\site-packages\telegram\ext\updater.py", line 319, in _network_loop_retry
    if not action_cb():
  File "C:\Users\ito0010\AppData\Local\Programs\Python\Python36\lib\site-packages\telegram\ext\updater.py", line 280, in polling_action_cb
    allowed_updates=allowed_updates)
  File "C:\Users\ito0010\AppData\Local\Programs\Python\Python36\lib\site-packages\telegram\bot.py", line 65, in decorator
    result = func(self, *args, **kwargs)
  File "C:\Users\ito0010\AppData\Local\Programs\Python\Python36\lib\site-packages\telegram\bot.py", line 1975, in get_updates
    result = self._request.post(url, data, timeout=float(read_latency) + float(timeout))
  File "C:\Users\ito0010\AppData\Local\Programs\Python\Python36\lib\site-packages\telegram\utils\request.py", line 309, in post
    headers={'Content-Type': 'application/json'})
  File "C:\Users\ito0010\AppData\Local\Programs\Python\Python36\lib\site-packages\telegram\utils\request.py", line 233, in _request_wrapper
    raise NetworkError('{0} ({1})'.format(message, resp.status))
telegram.error.NetworkError: Conflict: terminated by other getUpdates request; make sure that only one bot instance is running (409)
telegram.ext.updater - ERROR - Error while getting Updates: Conflict: terminated by other getUpdates request; make sure that only one bot instance is running (409)
telegram.ext.dispatcher - ERROR - No error handlers are registered, logging exception.
Traceback (most recent call last):
  File "C:\Users\ito0010\AppData\Local\Programs\Python\Python36\lib\site-packages\telegram\ext\updater.py", line 319, in _network_loop_retry
    if not action_cb():
  File "C:\Users\ito0010\AppData\Local\Programs\Python\Python36\lib\site-packages\telegram\ext\updater.py", line 280, in polling_action_cb
    allowed_updates=allowed_updates)
  File "C:\Users\ito0010\AppData\Local\Programs\Python\Python36\lib\site-packages\telegram\bot.py", line 65, in decorator
    result = func(self, *args, **kwargs)
  File "C:\Users\ito0010\AppData\Local\Programs\Python\Python36\lib\site-packages\telegram\bot.py", line 1975, in get_updates
    result = self._request.post(url, data, timeout=float(read_latency) + float(timeout))
  File "C:\Users\ito0010\AppData\Local\Programs\Python\Python36\lib\site-packages\telegram\utils\request.py", line 309, in post
    headers={'Content-Type': 'application/json'})
  File "C:\Users\ito0010\AppData\Local\Programs\Python\Python36\lib\site-packages\telegram\utils\request.py", line 233, in _request_wrapper
    raise NetworkError('{0} ({1})'.format(message, resp.status))
telegram.error.NetworkError: Conflict: terminated by other getUpdates request; make sure that only one bot instance is running (409)
telegram.ext.updater - ERROR - Error while getting Updates: Conflict: terminated by other getUpdates request; make sure that only one bot instance is running (409)
telegram.ext.dispatcher - ERROR - No error handlers are registered, logging exception.
Traceback (most recent call last):
  File "C:\Users\ito0010\AppData\Local\Programs\Python\Python36\lib\site-packages\telegram\ext\updater.py", line 319, in _network_loop_retry
    if not action_cb():
  File "C:\Users\ito0010\AppData\Local\Programs\Python\Python36\lib\site-packages\telegram\ext\updater.py", line 280, in polling_action_cb
    allowed_updates=allowed_updates)
  File "C:\Users\ito0010\AppData\Local\Programs\Python\Python36\lib\site-packages\telegram\bot.py", line 65, in decorator
    result = func(self, *args, **kwargs)
  File "C:\Users\ito0010\AppData\Local\Programs\Python\Python36\lib\site-packages\telegram\bot.py", line 1975, in get_updates
    result = self._request.post(url, data, timeout=float(read_latency) + float(timeout))
  File "C:\Users\ito0010\AppData\Local\Programs\Python\Python36\lib\site-packages\telegram\utils\request.py", line 309, in post
    headers={'Content-Type': 'application/json'})
  File "C:\Users\ito0010\AppData\Local\Programs\Python\Python36\lib\site-packages\telegram\utils\request.py", line 233, in _request_wrapper
    raise NetworkError('{0} ({1})'.format(message, resp.status))
telegram.error.NetworkError: Conflict: terminated by other getUpdates request; make sure that only one bot instance is running (409)
telegram.ext.updater - ERROR - Error while getting Updates: Conflict: terminated by other getUpdates request; make sure that only one bot instance is running (409)
telegram.ext.dispatcher - ERROR - No error handlers are registered, logging exception.
Traceback (most recent call last):
  File "C:\Users\ito0010\AppData\Local\Programs\Python\Python36\lib\site-packages\telegram\ext\updater.py", line 319, in _network_loop_retry
    if not action_cb():
  File "C:\Users\ito0010\AppData\Local\Programs\Python\Python36\lib\site-packages\telegram\ext\updater.py", line 280, in polling_action_cb
    allowed_updates=allowed_updates)
  File "C:\Users\ito0010\AppData\Local\Programs\Python\Python36\lib\site-packages\telegram\bot.py", line 65, in decorator
    result = func(self, *args, **kwargs)
  File "C:\Users\ito0010\AppData\Local\Programs\Python\Python36\lib\site-packages\telegram\bot.py", line 1975, in get_updates
    result = self._request.post(url, data, timeout=float(read_latency) + float(timeout))
  File "C:\Users\ito0010\AppData\Local\Programs\Python\Python36\lib\site-packages\telegram\utils\request.py", line 309, in post
    headers={'Content-Type': 'application/json'})
  File "C:\Users\ito0010\AppData\Local\Programs\Python\Python36\lib\site-packages\telegram\utils\request.py", line 233, in _request_wrapper
    raise NetworkError('{0} ({1})'.format(message, resp.status))
telegram.error.NetworkError: Conflict: terminated by other getUpdates request; make sure that only one bot instance is running (409)
telegram.ext.updater - ERROR - Error while getting Updates: Conflict: terminated by other getUpdates request; make sure that only one bot instance is running (409)
telegram.ext.dispatcher - ERROR - No error handlers are registered, logging exception.
Traceback (most recent call last):
  File "C:\Users\ito0010\AppData\Local\Programs\Python\Python36\lib\site-packages\telegram\ext\updater.py", line 319, in _network_loop_retry
    if not action_cb():
  File "C:\Users\ito0010\AppData\Local\Programs\Python\Python36\lib\site-packages\telegram\ext\updater.py", line 280, in polling_action_cb
    allowed_updates=allowed_updates)
  File "C:\Users\ito0010\AppData\Local\Programs\Python\Python36\lib\site-packages\telegram\bot.py", line 65, in decorator
    result = func(self, *args, **kwargs)
  File "C:\Users\ito0010\AppData\Local\Programs\Python\Python36\lib\site-packages\telegram\bot.py", line 1975, in get_updates
    result = self._request.post(url, data, timeout=float(read_latency) + float(timeout))
  File "C:\Users\ito0010\AppData\Local\Programs\Python\Python36\lib\site-packages\telegram\utils\request.py", line 309, in post
    headers={'Content-Type': 'application/json'})
  File "C:\Users\ito0010\AppData\Local\Programs\Python\Python36\lib\site-packages\telegram\utils\request.py", line 233, in _request_wrapper
    raise NetworkError('{0} ({1})'.format(message, resp.status))
telegram.error.NetworkError: Conflict: terminated by other getUpdates request; make sure that only one bot instance is running (409)
telegram.ext.updater - ERROR - Error while getting Updates: Conflict: terminated by other getUpdates request; make sure that only one bot instance is running (409)
telegram.ext.dispatcher - ERROR - No error handlers are registered, logging exception.
Traceback (most recent call last):
  File "C:\Users\ito0010\AppData\Local\Programs\Python\Python36\lib\site-packages\telegram\ext\updater.py", line 319, in _network_loop_retry
    if not action_cb():
  File "C:\Users\ito0010\AppData\Local\Programs\Python\Python36\lib\site-packages\telegram\ext\updater.py", line 280, in polling_action_cb
    allowed_updates=allowed_updates)
  File "C:\Users\ito0010\AppData\Local\Programs\Python\Python36\lib\site-packages\telegram\bot.py", line 65, in decorator
    result = func(self, *args, **kwargs)
  File "C:\Users\ito0010\AppData\Local\Programs\Python\Python36\lib\site-packages\telegram\bot.py", line 1975, in get_updates
    result = self._request.post(url, data, timeout=float(read_latency) + float(timeout))
  File "C:\Users\ito0010\AppData\Local\Programs\Python\Python36\lib\site-packages\telegram\utils\request.py", line 309, in post
    headers={'Content-Type': 'application/json'})
  File "C:\Users\ito0010\AppData\Local\Programs\Python\Python36\lib\site-packages\telegram\utils\request.py", line 233, in _request_wrapper
    raise NetworkError('{0} ({1})'.format(message, resp.status))
telegram.error.NetworkError: Conflict: terminated by other getUpdates request; make sure that only one bot instance is running (409)
telegram.ext.updater - ERROR - Error while getting Updates: Conflict: terminated by other getUpdates request; make sure that only one bot instance is running (409)
telegram.ext.dispatcher - ERROR - No error handlers are registered, logging exception.
Traceback (most recent call last):
  File "C:\Users\ito0010\AppData\Local\Programs\Python\Python36\lib\site-packages\telegram\ext\updater.py", line 319, in _network_loop_retry
    if not action_cb():
  File "C:\Users\ito0010\AppData\Local\Programs\Python\Python36\lib\site-packages\telegram\ext\updater.py", line 280, in polling_action_cb
    allowed_updates=allowed_updates)
  File "C:\Users\ito0010\AppData\Local\Programs\Python\Python36\lib\site-packages\telegram\bot.py", line 65, in decorator
    result = func(self, *args, **kwargs)
  File "C:\Users\ito0010\AppData\Local\Programs\Python\Python36\lib\site-packages\telegram\bot.py", line 1975, in get_updates
    result = self._request.post(url, data, timeout=float(read_latency) + float(timeout))
  File "C:\Users\ito0010\AppData\Local\Programs\Python\Python36\lib\site-packages\telegram\utils\request.py", line 309, in post
    headers={'Content-Type': 'application/json'})
  File "C:\Users\ito0010\AppData\Local\Programs\Python\Python36\lib\site-packages\telegram\utils\request.py", line 233, in _request_wrapper
    raise NetworkError('{0} ({1})'.format(message, resp.status))
telegram.error.NetworkError: Conflict: terminated by other getUpdates request; make sure that only one bot instance is running (409)
telegram.ext.updater - ERROR - Error while getting Updates: Conflict: terminated by other getUpdates request; make sure that only one bot instance is running (409)
telegram.ext.dispatcher - ERROR - No error handlers are registered, logging exception.
Traceback (most recent call last):
  File "C:\Users\ito0010\AppData\Local\Programs\Python\Python36\lib\site-packages\telegram\ext\updater.py", line 319, in _network_loop_retry
    if not action_cb():
  File "C:\Users\ito0010\AppData\Local\Programs\Python\Python36\lib\site-packages\telegram\ext\updater.py", line 280, in polling_action_cb
    allowed_updates=allowed_updates)
  File "C:\Users\ito0010\AppData\Local\Programs\Python\Python36\lib\site-packages\telegram\bot.py", line 65, in decorator
    result = func(self, *args, **kwargs)
  File "C:\Users\ito0010\AppData\Local\Programs\Python\Python36\lib\site-packages\telegram\bot.py", line 1975, in get_updates
    result = self._request.post(url, data, timeout=float(read_latency) + float(timeout))
  File "C:\Users\ito0010\AppData\Local\Programs\Python\Python36\lib\site-packages\telegram\utils\request.py", line 309, in post
    headers={'Content-Type': 'application/json'})
  File "C:\Users\ito0010\AppData\Local\Programs\Python\Python36\lib\site-packages\telegram\utils\request.py", line 233, in _request_wrapper
    raise NetworkError('{0} ({1})'.format(message, resp.status))
telegram.error.NetworkError: Conflict: terminated by other getUpdates request; make sure that only one bot instance is running (409)
telegram.ext.updater - INFO - Received signal 2 (SIGINT), stopping...
telegram.ext.updater - WARNING - Exiting immediately!
telegram.ext.updater - ERROR - Error while getting Updates: Conflict: terminated by other getUpdates request; make sure that only one bot instance is running (409)
telegram.ext.dispatcher - ERROR - No error handlers are registered, logging exception.
Traceback (most recent call last):
  File "C:\Users\ito0010\AppData\Local\Programs\Python\Python36\lib\site-packages\telegram\ext\updater.py", line 319, in _network_loop_retry
    if not action_cb():
  File "C:\Users\ito0010\AppData\Local\Programs\Python\Python36\lib\site-packages\telegram\ext\updater.py", line 280, in polling_action_cb
    allowed_updates=allowed_updates)
  File "C:\Users\ito0010\AppData\Local\Programs\Python\Python36\lib\site-packages\telegram\bot.py", line 65, in decorator
    result = func(self, *args, **kwargs)
  File "C:\Users\ito0010\AppData\Local\Programs\Python\Python36\lib\site-packages\telegram\bot.py", line 1975, in get_updates
    result = self._request.post(url, data, timeout=float(read_latency) + float(timeout))
  File "C:\Users\ito0010\AppData\Local\Programs\Python\Python36\lib\site-packages\telegram\utils\request.py", line 309, in post
    headers={'Content-Type': 'application/json'})
  File "C:\Users\ito0010\AppData\Local\Programs\Python\Python36\lib\site-packages\telegram\utils\request.py", line 233, in _request_wrapper
    raise NetworkError('{0} ({1})'.format(message, resp.status))
telegram.error.NetworkError: Conflict: terminated by other getUpdates request; make sure that only one bot instance is running (409)
telegram.ext.updater - ERROR - Error while getting Updates: Conflict: terminated by other getUpdates request; make sure that only one bot instance is running (409)
telegram.ext.dispatcher - ERROR - An uncaught error was raised while processing the update
Traceback (most recent call last):
  File "C:\Users\ito0010\AppData\Local\Programs\Python\Python36\lib\site-packages\telegram\ext\dispatcher.py", line 279, in process_update
    handler.handle_update(update, self)
  File "C:\Users\ito0010\AppData\Local\Programs\Python\Python36\lib\site-packages\telegram\ext\commandhandler.py", line 173, in handle_update
    return self.callback(dispatcher.bot, update, **optional_args)
  File "c:\LearnPython\Lesson2\bot.py", line 29, in planet_user
    today = datetime.strftime(datetime.now(), '%Y/%m/%d')
AttributeError: module 'datetime' has no attribute 'strftime'
telegram.ext.dispatcher - ERROR - No error handlers are registered, logging exception.
Traceback (most recent call last):
  File "C:\Users\ito0010\AppData\Local\Programs\Python\Python36\lib\site-packages\telegram\ext\updater.py", line 319, in _network_loop_retry
    if not action_cb():
  File "C:\Users\ito0010\AppData\Local\Programs\Python\Python36\lib\site-packages\telegram\ext\updater.py", line 280, in polling_action_cb
    allowed_updates=allowed_updates)
  File "C:\Users\ito0010\AppData\Local\Programs\Python\Python36\lib\site-packages\telegram\bot.py", line 65, in decorator
    result = func(self, *args, **kwargs)
  File "C:\Users\ito0010\AppData\Local\Programs\Python\Python36\lib\site-packages\telegram\bot.py", line 1975, in get_updates
    result = self._request.post(url, data, timeout=float(read_latency) + float(timeout))
  File "C:\Users\ito0010\AppData\Local\Programs\Python\Python36\lib\site-packages\telegram\utils\request.py", line 309, in post
    headers={'Content-Type': 'application/json'})
  File "C:\Users\ito0010\AppData\Local\Programs\Python\Python36\lib\site-packages\telegram\utils\request.py", line 233, in _request_wrapper
    raise NetworkError('{0} ({1})'.format(message, resp.status))
telegram.error.NetworkError: Conflict: terminated by other getUpdates request; make sure that only one bot instance is running (409)
telegram.ext.updater - ERROR - Error while getting Updates: Conflict: terminated by other getUpdates request; make sure that only one bot instance is running (409)
telegram.ext.dispatcher - ERROR - No error handlers are registered, logging exception.
Traceback (most recent call last):
  File "C:\Users\ito0010\AppData\Local\Programs\Python\Python36\lib\site-packages\telegram\ext\updater.py", line 319, in _network_loop_retry
    if not action_cb():
  File "C:\Users\ito0010\AppData\Local\Programs\Python\Python36\lib\site-packages\telegram\ext\updater.py", line 280, in polling_action_cb
    allowed_updates=allowed_updates)
  File "C:\Users\ito0010\AppData\Local\Programs\Python\Python36\lib\site-packages\telegram\bot.py", line 65, in decorator
    result = func(self, *args, **kwargs)
  File "C:\Users\ito0010\AppData\Local\Programs\Python\Python36\lib\site-packages\telegram\bot.py", line 1975, in get_updates
    result = self._request.post(url, data, timeout=float(read_latency) + float(timeout))
  File "C:\Users\ito0010\AppData\Local\Programs\Python\Python36\lib\site-packages\telegram\utils\request.py", line 309, in post
    headers={'Content-Type': 'application/json'})
  File "C:\Users\ito0010\AppData\Local\Programs\Python\Python36\lib\site-packages\telegram\utils\request.py", line 233, in _request_wrapper
    raise NetworkError('{0} ({1})'.format(message, resp.status))
telegram.error.NetworkError: Conflict: terminated by other getUpdates request; make sure that only one bot instance is running (409)
telegram.ext.updater - ERROR - Error while getting Updates: Conflict: terminated by other getUpdates request; make sure that only one bot instance is running (409)
telegram.ext.dispatcher - ERROR - No error handlers are registered, logging exception.
Traceback (most recent call last):
  File "C:\Users\ito0010\AppData\Local\Programs\Python\Python36\lib\site-packages\telegram\ext\updater.py", line 319, in _network_loop_retry
    if not action_cb():
  File "C:\Users\ito0010\AppData\Local\Programs\Python\Python36\lib\site-packages\telegram\ext\updater.py", line 280, in polling_action_cb
    allowed_updates=allowed_updates)
  File "C:\Users\ito0010\AppData\Local\Programs\Python\Python36\lib\site-packages\telegram\bot.py", line 65, in decorator
    result = func(self, *args, **kwargs)
  File "C:\Users\ito0010\AppData\Local\Programs\Python\Python36\lib\site-packages\telegram\bot.py", line 1975, in get_updates
    result = self._request.post(url, data, timeout=float(read_latency) + float(timeout))
  File "C:\Users\ito0010\AppData\Local\Programs\Python\Python36\lib\site-packages\telegram\utils\request.py", line 309, in post
    headers={'Content-Type': 'application/json'})
  File "C:\Users\ito0010\AppData\Local\Programs\Python\Python36\lib\site-packages\telegram\utils\request.py", line 233, in _request_wrapper
    raise NetworkError('{0} ({1})'.format(message, resp.status))
telegram.error.NetworkError: Conflict: terminated by other getUpdates request; make sure that only one bot instance is running (409)
telegram.ext.updater - ERROR - Error while getting Updates: Conflict: terminated by other getUpdates request; make sure that only one bot instance is running (409)
telegram.ext.dispatcher - ERROR - No error handlers are registered, logging exception.
Traceback (most recent call last):
  File "C:\Users\ito0010\AppData\Local\Programs\Python\Python36\lib\site-packages\telegram\ext\updater.py", line 319, in _network_loop_retry
    if not action_cb():
  File "C:\Users\ito0010\AppData\Local\Programs\Python\Python36\lib\site-packages\telegram\ext\updater.py", line 280, in polling_action_cb
    allowed_updates=allowed_updates)
  File "C:\Users\ito0010\AppData\Local\Programs\Python\Python36\lib\site-packages\telegram\bot.py", line 65, in decorator
    result = func(self, *args, **kwargs)
  File "C:\Users\ito0010\AppData\Local\Programs\Python\Python36\lib\site-packages\telegram\bot.py", line 1975, in get_updates
    result = self._request.post(url, data, timeout=float(read_latency) + float(timeout))
  File "C:\Users\ito0010\AppData\Local\Programs\Python\Python36\lib\site-packages\telegram\utils\request.py", line 309, in post
    headers={'Content-Type': 'application/json'})
  File "C:\Users\ito0010\AppData\Local\Programs\Python\Python36\lib\site-packages\telegram\utils\request.py", line 233, in _request_wrapper
    raise NetworkError('{0} ({1})'.format(message, resp.status))
telegram.error.NetworkError: Conflict: terminated by other getUpdates request; make sure that only one bot instance is running (409)
telegram.ext.updater - ERROR - Error while getting Updates: Conflict: terminated by other getUpdates request; make sure that only one bot instance is running (409)
telegram.ext.dispatcher - ERROR - No error handlers are registered, logging exception.
Traceback (most recent call last):
  File "C:\Users\ito0010\AppData\Local\Programs\Python\Python36\lib\site-packages\telegram\ext\updater.py", line 319, in _network_loop_retry
    if not action_cb():
  File "C:\Users\ito0010\AppData\Local\Programs\Python\Python36\lib\site-packages\telegram\ext\updater.py", line 280, in polling_action_cb
    allowed_updates=allowed_updates)
  File "C:\Users\ito0010\AppData\Local\Programs\Python\Python36\lib\site-packages\telegram\bot.py", line 65, in decorator
    result = func(self, *args, **kwargs)
  File "C:\Users\ito0010\AppData\Local\Programs\Python\Python36\lib\site-packages\telegram\bot.py", line 1975, in get_updates
    result = self._request.post(url, data, timeout=float(read_latency) + float(timeout))
  File "C:\Users\ito0010\AppData\Local\Programs\Python\Python36\lib\site-packages\telegram\utils\request.py", line 309, in post
    headers={'Content-Type': 'application/json'})
  File "C:\Users\ito0010\AppData\Local\Programs\Python\Python36\lib\site-packages\telegram\utils\request.py", line 233, in _request_wrapper
    raise NetworkError('{0} ({1})'.format(message, resp.status))
telegram.error.NetworkError: Conflict: terminated by other getUpdates request; make sure that only one bot instance is running (409)
telegram.ext.updater - ERROR - Error while getting Updates: Conflict: terminated by other getUpdates request; make sure that only one bot instance is running (409)
telegram.ext.dispatcher - ERROR - No error handlers are registered, logging exception.
Traceback (most recent call last):
  File "C:\Users\ito0010\AppData\Local\Programs\Python\Python36\lib\site-packages\telegram\ext\updater.py", line 319, in _network_loop_retry
    if not action_cb():
  File "C:\Users\ito0010\AppData\Local\Programs\Python\Python36\lib\site-packages\telegram\ext\updater.py", line 280, in polling_action_cb
    allowed_updates=allowed_updates)
  File "C:\Users\ito0010\AppData\Local\Programs\Python\Python36\lib\site-packages\telegram\bot.py", line 65, in decorator
    result = func(self, *args, **kwargs)
  File "C:\Users\ito0010\AppData\Local\Programs\Python\Python36\lib\site-packages\telegram\bot.py", line 1975, in get_updates
    result = self._request.post(url, data, timeout=float(read_latency) + float(timeout))
  File "C:\Users\ito0010\AppData\Local\Programs\Python\Python36\lib\site-packages\telegram\utils\request.py", line 309, in post
    headers={'Content-Type': 'application/json'})
  File "C:\Users\ito0010\AppData\Local\Programs\Python\Python36\lib\site-packages\telegram\utils\request.py", line 233, in _request_wrapper
    raise NetworkError('{0} ({1})'.format(message, resp.status))
telegram.error.NetworkError: Conflict: terminated by other getUpdates request; make sure that only one bot instance is running (409)
telegram.ext.updater - ERROR - Error while getting Updates: Conflict: terminated by other getUpdates request; make sure that only one bot instance is running (409)
telegram.ext.dispatcher - ERROR - No error handlers are registered, logging exception.
Traceback (most recent call last):
  File "C:\Users\ito0010\AppData\Local\Programs\Python\Python36\lib\site-packages\telegram\ext\updater.py", line 319, in _network_loop_retry
    if not action_cb():
  File "C:\Users\ito0010\AppData\Local\Programs\Python\Python36\lib\site-packages\telegram\ext\updater.py", line 280, in polling_action_cb
    allowed_updates=allowed_updates)
  File "C:\Users\ito0010\AppData\Local\Programs\Python\Python36\lib\site-packages\telegram\bot.py", line 65, in decorator
    result = func(self, *args, **kwargs)
  File "C:\Users\ito0010\AppData\Local\Programs\Python\Python36\lib\site-packages\telegram\bot.py", line 1975, in get_updates
    result = self._request.post(url, data, timeout=float(read_latency) + float(timeout))
  File "C:\Users\ito0010\AppData\Local\Programs\Python\Python36\lib\site-packages\telegram\utils\request.py", line 309, in post
    headers={'Content-Type': 'application/json'})
  File "C:\Users\ito0010\AppData\Local\Programs\Python\Python36\lib\site-packages\telegram\utils\request.py", line 233, in _request_wrapper
    raise NetworkError('{0} ({1})'.format(message, resp.status))
telegram.error.NetworkError: Conflict: terminated by other getUpdates request; make sure that only one bot instance is running (409)
telegram.ext.updater - ERROR - Error while getting Updates: Conflict: terminated by other getUpdates request; make sure that only one bot instance is running (409)
telegram.ext.dispatcher - ERROR - No error handlers are registered, logging exception.
Traceback (most recent call last):
  File "C:\Users\ito0010\AppData\Local\Programs\Python\Python36\lib\site-packages\telegram\ext\updater.py", line 319, in _network_loop_retry
    if not action_cb():
  File "C:\Users\ito0010\AppData\Local\Programs\Python\Python36\lib\site-packages\telegram\ext\updater.py", line 280, in polling_action_cb
    allowed_updates=allowed_updates)
  File "C:\Users\ito0010\AppData\Local\Programs\Python\Python36\lib\site-packages\telegram\bot.py", line 65, in decorator
    result = func(self, *args, **kwargs)
  File "C:\Users\ito0010\AppData\Local\Programs\Python\Python36\lib\site-packages\telegram\bot.py", line 1975, in get_updates
    result = self._request.post(url, data, timeout=float(read_latency) + float(timeout))
  File "C:\Users\ito0010\AppData\Local\Programs\Python\Python36\lib\site-packages\telegram\utils\request.py", line 309, in post
    headers={'Content-Type': 'application/json'})
  File "C:\Users\ito0010\AppData\Local\Programs\Python\Python36\lib\site-packages\telegram\utils\request.py", line 233, in _request_wrapper
    raise NetworkError('{0} ({1})'.format(message, resp.status))
telegram.error.NetworkError: Conflict: terminated by other getUpdates request; make sure that only one bot instance is running (409)
telegram.ext.updater - ERROR - Error while getting Updates: Conflict: terminated by other getUpdates request; make sure that only one bot instance is running (409)
telegram.ext.dispatcher - ERROR - No error handlers are registered, logging exception.
Traceback (most recent call last):
  File "C:\Users\ito0010\AppData\Local\Programs\Python\Python36\lib\site-packages\telegram\ext\updater.py", line 319, in _network_loop_retry
    if not action_cb():
  File "C:\Users\ito0010\AppData\Local\Programs\Python\Python36\lib\site-packages\telegram\ext\updater.py", line 280, in polling_action_cb
    allowed_updates=allowed_updates)
  File "C:\Users\ito0010\AppData\Local\Programs\Python\Python36\lib\site-packages\telegram\bot.py", line 65, in decorator
    result = func(self, *args, **kwargs)
  File "C:\Users\ito0010\AppData\Local\Programs\Python\Python36\lib\site-packages\telegram\bot.py", line 1975, in get_updates
    result = self._request.post(url, data, timeout=float(read_latency) + float(timeout))
  File "C:\Users\ito0010\AppData\Local\Programs\Python\Python36\lib\site-packages\telegram\utils\request.py", line 309, in post
    headers={'Content-Type': 'application/json'})
  File "C:\Users\ito0010\AppData\Local\Programs\Python\Python36\lib\site-packages\telegram\utils\request.py", line 233, in _request_wrapper
    raise NetworkError('{0} ({1})'.format(message, resp.status))
telegram.error.NetworkError: Conflict: terminated by other getUpdates request; make sure that only one bot instance is running (409)
telegram.ext.updater - ERROR - Error while getting Updates: Conflict: terminated by other getUpdates request; make sure that only one bot instance is running (409)
telegram.ext.dispatcher - ERROR - No error handlers are registered, logging exception.
Traceback (most recent call last):
  File "C:\Users\ito0010\AppData\Local\Programs\Python\Python36\lib\site-packages\telegram\ext\updater.py", line 319, in _network_loop_retry
    if not action_cb():
  File "C:\Users\ito0010\AppData\Local\Programs\Python\Python36\lib\site-packages\telegram\ext\updater.py", line 280, in polling_action_cb
    allowed_updates=allowed_updates)
  File "C:\Users\ito0010\AppData\Local\Programs\Python\Python36\lib\site-packages\telegram\bot.py", line 65, in decorator
    result = func(self, *args, **kwargs)
  File "C:\Users\ito0010\AppData\Local\Programs\Python\Python36\lib\site-packages\telegram\bot.py", line 1975, in get_updates
    result = self._request.post(url, data, timeout=float(read_latency) + float(timeout))
  File "C:\Users\ito0010\AppData\Local\Programs\Python\Python36\lib\site-packages\telegram\utils\request.py", line 309, in post
    headers={'Content-Type': 'application/json'})
  File "C:\Users\ito0010\AppData\Local\Programs\Python\Python36\lib\site-packages\telegram\utils\request.py", line 233, in _request_wrapper
    raise NetworkError('{0} ({1})'.format(message, resp.status))
telegram.error.NetworkError: Conflict: terminated by other getUpdates request; make sure that only one bot instance is running (409)
telegram.ext.updater - ERROR - Error while getting Updates: Conflict: terminated by other getUpdates request; make sure that only one bot instance is running (409)
telegram.ext.dispatcher - ERROR - No error handlers are registered, logging exception.
Traceback (most recent call last):
  File "C:\Users\ito0010\AppData\Local\Programs\Python\Python36\lib\site-packages\telegram\ext\updater.py", line 319, in _network_loop_retry
    if not action_cb():
  File "C:\Users\ito0010\AppData\Local\Programs\Python\Python36\lib\site-packages\telegram\ext\updater.py", line 280, in polling_action_cb
    allowed_updates=allowed_updates)
  File "C:\Users\ito0010\AppData\Local\Programs\Python\Python36\lib\site-packages\telegram\bot.py", line 65, in decorator
    result = func(self, *args, **kwargs)
  File "C:\Users\ito0010\AppData\Local\Programs\Python\Python36\lib\site-packages\telegram\bot.py", line 1975, in get_updates
    result = self._request.post(url, data, timeout=float(read_latency) + float(timeout))
  File "C:\Users\ito0010\AppData\Local\Programs\Python\Python36\lib\site-packages\telegram\utils\request.py", line 309, in post
    headers={'Content-Type': 'application/json'})
  File "C:\Users\ito0010\AppData\Local\Programs\Python\Python36\lib\site-packages\telegram\utils\request.py", line 233, in _request_wrapper
    raise NetworkError('{0} ({1})'.format(message, resp.status))
telegram.error.NetworkError: Conflict: terminated by other getUpdates request; make sure that only one bot instance is running (409)
telegram.ext.updater - ERROR - Error while getting Updates: Conflict: terminated by other getUpdates request; make sure that only one bot instance is running (409)
telegram.ext.dispatcher - ERROR - No error handlers are registered, logging exception.
Traceback (most recent call last):
  File "C:\Users\ito0010\AppData\Local\Programs\Python\Python36\lib\site-packages\telegram\ext\updater.py", line 319, in _network_loop_retry
    if not action_cb():
  File "C:\Users\ito0010\AppData\Local\Programs\Python\Python36\lib\site-packages\telegram\ext\updater.py", line 280, in polling_action_cb
    allowed_updates=allowed_updates)
  File "C:\Users\ito0010\AppData\Local\Programs\Python\Python36\lib\site-packages\telegram\bot.py", line 65, in decorator
    result = func(self, *args, **kwargs)
  File "C:\Users\ito0010\AppData\Local\Programs\Python\Python36\lib\site-packages\telegram\bot.py", line 1975, in get_updates
    result = self._request.post(url, data, timeout=float(read_latency) + float(timeout))
  File "C:\Users\ito0010\AppData\Local\Programs\Python\Python36\lib\site-packages\telegram\utils\request.py", line 309, in post
    headers={'Content-Type': 'application/json'})
  File "C:\Users\ito0010\AppData\Local\Programs\Python\Python36\lib\site-packages\telegram\utils\request.py", line 233, in _request_wrapper
    raise NetworkError('{0} ({1})'.format(message, resp.status))
telegram.error.NetworkError: Conflict: terminated by other getUpdates request; make sure that only one bot instance is running (409)
telegram.ext.updater - ERROR - Error while getting Updates: Conflict: terminated by other getUpdates request; make sure that only one bot instance is running (409)
telegram.ext.dispatcher - ERROR - No error handlers are registered, logging exception.
Traceback (most recent call last):
  File "C:\Users\ito0010\AppData\Local\Programs\Python\Python36\lib\site-packages\telegram\ext\updater.py", line 319, in _network_loop_retry
    if not action_cb():
  File "C:\Users\ito0010\AppData\Local\Programs\Python\Python36\lib\site-packages\telegram\ext\updater.py", line 280, in polling_action_cb
    allowed_updates=allowed_updates)
  File "C:\Users\ito0010\AppData\Local\Programs\Python\Python36\lib\site-packages\telegram\bot.py", line 65, in decorator
    result = func(self, *args, **kwargs)
  File "C:\Users\ito0010\AppData\Local\Programs\Python\Python36\lib\site-packages\telegram\bot.py", line 1975, in get_updates
    result = self._request.post(url, data, timeout=float(read_latency) + float(timeout))
  File "C:\Users\ito0010\AppData\Local\Programs\Python\Python36\lib\site-packages\telegram\utils\request.py", line 309, in post
    headers={'Content-Type': 'application/json'})
  File "C:\Users\ito0010\AppData\Local\Programs\Python\Python36\lib\site-packages\telegram\utils\request.py", line 233, in _request_wrapper
    raise NetworkError('{0} ({1})'.format(message, resp.status))
telegram.error.NetworkError: Conflict: terminated by other getUpdates request; make sure that only one bot instance is running (409)
telegram.ext.updater - ERROR - Error while getting Updates: Conflict: terminated by other getUpdates request; make sure that only one bot instance is running (409)
telegram.ext.dispatcher - ERROR - No error handlers are registered, logging exception.
Traceback (most recent call last):
  File "C:\Users\ito0010\AppData\Local\Programs\Python\Python36\lib\site-packages\telegram\ext\updater.py", line 319, in _network_loop_retry
    if not action_cb():
  File "C:\Users\ito0010\AppData\Local\Programs\Python\Python36\lib\site-packages\telegram\ext\updater.py", line 280, in polling_action_cb
    allowed_updates=allowed_updates)
  File "C:\Users\ito0010\AppData\Local\Programs\Python\Python36\lib\site-packages\telegram\bot.py", line 65, in decorator
    result = func(self, *args, **kwargs)
  File "C:\Users\ito0010\AppData\Local\Programs\Python\Python36\lib\site-packages\telegram\bot.py", line 1975, in get_updates
    result = self._request.post(url, data, timeout=float(read_latency) + float(timeout))
  File "C:\Users\ito0010\AppData\Local\Programs\Python\Python36\lib\site-packages\telegram\utils\request.py", line 309, in post
    headers={'Content-Type': 'application/json'})
  File "C:\Users\ito0010\AppData\Local\Programs\Python\Python36\lib\site-packages\telegram\utils\request.py", line 233, in _request_wrapper
    raise NetworkError('{0} ({1})'.format(message, resp.status))
telegram.error.NetworkError: Conflict: terminated by other getUpdates request; make sure that only one bot instance is running (409)
telegram.ext.updater - ERROR - Error while getting Updates: Conflict: terminated by other getUpdates request; make sure that only one bot instance is running (409)
telegram.ext.dispatcher - ERROR - No error handlers are registered, logging exception.
Traceback (most recent call last):
  File "C:\Users\ito0010\AppData\Local\Programs\Python\Python36\lib\site-packages\telegram\ext\updater.py", line 319, in _network_loop_retry
    if not action_cb():
  File "C:\Users\ito0010\AppData\Local\Programs\Python\Python36\lib\site-packages\telegram\ext\updater.py", line 280, in polling_action_cb
    allowed_updates=allowed_updates)
  File "C:\Users\ito0010\AppData\Local\Programs\Python\Python36\lib\site-packages\telegram\bot.py", line 65, in decorator
    result = func(self, *args, **kwargs)
  File "C:\Users\ito0010\AppData\Local\Programs\Python\Python36\lib\site-packages\telegram\bot.py", line 1975, in get_updates
    result = self._request.post(url, data, timeout=float(read_latency) + float(timeout))
  File "C:\Users\ito0010\AppData\Local\Programs\Python\Python36\lib\site-packages\telegram\utils\request.py", line 309, in post
    headers={'Content-Type': 'application/json'})
  File "C:\Users\ito0010\AppData\Local\Programs\Python\Python36\lib\site-packages\telegram\utils\request.py", line 233, in _request_wrapper
    raise NetworkError('{0} ({1})'.format(message, resp.status))
telegram.error.NetworkError: Conflict: terminated by other getUpdates request; make sure that only one bot instance is running (409)
telegram.ext.updater - INFO - Received signal 2 (SIGINT), stopping...
telegram.ext.dispatcher - ERROR - An uncaught error was raised while processing the update
Traceback (most recent call last):
  File "C:\Users\ito0010\AppData\Local\Programs\Python\Python36\lib\site-packages\telegram\ext\dispatcher.py", line 279, in process_update
    handler.handle_update(update, self)
  File "C:\Users\ito0010\AppData\Local\Programs\Python\Python36\lib\site-packages\telegram\ext\commandhandler.py", line 173, in handle_update
    return self.callback(dispatcher.bot, update, **optional_args)
  File "c:\LearnPython\Lesson2\bot.py", line 30, in planet_user
    print(today)
NameError: name 'today' is not defined
telegram.ext.updater - ERROR - Error while getting Updates: Conflict: terminated by other getUpdates request; make sure that only one bot instance is running (409)
telegram.ext.dispatcher - ERROR - No error handlers are registered, logging exception.
Traceback (most recent call last):
  File "C:\Users\ito0010\AppData\Local\Programs\Python\Python36\lib\site-packages\telegram\ext\updater.py", line 319, in _network_loop_retry
    if not action_cb():
  File "C:\Users\ito0010\AppData\Local\Programs\Python\Python36\lib\site-packages\telegram\ext\updater.py", line 280, in polling_action_cb
    allowed_updates=allowed_updates)
  File "C:\Users\ito0010\AppData\Local\Programs\Python\Python36\lib\site-packages\telegram\bot.py", line 65, in decorator
    result = func(self, *args, **kwargs)
  File "C:\Users\ito0010\AppData\Local\Programs\Python\Python36\lib\site-packages\telegram\bot.py", line 1975, in get_updates
    result = self._request.post(url, data, timeout=float(read_latency) + float(timeout))
  File "C:\Users\ito0010\AppData\Local\Programs\Python\Python36\lib\site-packages\telegram\utils\request.py", line 309, in post
    headers={'Content-Type': 'application/json'})
  File "C:\Users\ito0010\AppData\Local\Programs\Python\Python36\lib\site-packages\telegram\utils\request.py", line 233, in _request_wrapper
    raise NetworkError('{0} ({1})'.format(message, resp.status))
telegram.error.NetworkError: Conflict: terminated by other getUpdates request; make sure that only one bot instance is running (409)
telegram.ext.updater - ERROR - Error while getting Updates: Conflict: terminated by other getUpdates request; make sure that only one bot instance is running (409)
telegram.ext.dispatcher - ERROR - No error handlers are registered, logging exception.
Traceback (most recent call last):
  File "C:\Users\ito0010\AppData\Local\Programs\Python\Python36\lib\site-packages\telegram\ext\updater.py", line 319, in _network_loop_retry
    if not action_cb():
  File "C:\Users\ito0010\AppData\Local\Programs\Python\Python36\lib\site-packages\telegram\ext\updater.py", line 280, in polling_action_cb
    allowed_updates=allowed_updates)
  File "C:\Users\ito0010\AppData\Local\Programs\Python\Python36\lib\site-packages\telegram\bot.py", line 65, in decorator
    result = func(self, *args, **kwargs)
  File "C:\Users\ito0010\AppData\Local\Programs\Python\Python36\lib\site-packages\telegram\bot.py", line 1975, in get_updates
    result = self._request.post(url, data, timeout=float(read_latency) + float(timeout))
  File "C:\Users\ito0010\AppData\Local\Programs\Python\Python36\lib\site-packages\telegram\utils\request.py", line 309, in post
    headers={'Content-Type': 'application/json'})
  File "C:\Users\ito0010\AppData\Local\Programs\Python\Python36\lib\site-packages\telegram\utils\request.py", line 233, in _request_wrapper
    raise NetworkError('{0} ({1})'.format(message, resp.status))
telegram.error.NetworkError: Conflict: terminated by other getUpdates request; make sure that only one bot instance is running (409)
telegram.ext.updater - ERROR - Error while getting Updates: Conflict: terminated by other getUpdates request; make sure that only one bot instance is running (409)
telegram.ext.dispatcher - ERROR - No error handlers are registered, logging exception.
Traceback (most recent call last):
  File "C:\Users\ito0010\AppData\Local\Programs\Python\Python36\lib\site-packages\telegram\ext\updater.py", line 319, in _network_loop_retry
    if not action_cb():
  File "C:\Users\ito0010\AppData\Local\Programs\Python\Python36\lib\site-packages\telegram\ext\updater.py", line 280, in polling_action_cb
    allowed_updates=allowed_updates)
  File "C:\Users\ito0010\AppData\Local\Programs\Python\Python36\lib\site-packages\telegram\bot.py", line 65, in decorator
    result = func(self, *args, **kwargs)
  File "C:\Users\ito0010\AppData\Local\Programs\Python\Python36\lib\site-packages\telegram\bot.py", line 1975, in get_updates
    result = self._request.post(url, data, timeout=float(read_latency) + float(timeout))
  File "C:\Users\ito0010\AppData\Local\Programs\Python\Python36\lib\site-packages\telegram\utils\request.py", line 309, in post
    headers={'Content-Type': 'application/json'})
  File "C:\Users\ito0010\AppData\Local\Programs\Python\Python36\lib\site-packages\telegram\utils\request.py", line 233, in _request_wrapper
    raise NetworkError('{0} ({1})'.format(message, resp.status))
telegram.error.NetworkError: Conflict: terminated by other getUpdates request; make sure that only one bot instance is running (409)
telegram.ext.updater - ERROR - Error while getting Updates: Conflict: terminated by other getUpdates request; make sure that only one bot instance is running (409)
telegram.ext.dispatcher - ERROR - No error handlers are registered, logging exception.
Traceback (most recent call last):
  File "C:\Users\ito0010\AppData\Local\Programs\Python\Python36\lib\site-packages\telegram\ext\updater.py", line 319, in _network_loop_retry
    if not action_cb():
  File "C:\Users\ito0010\AppData\Local\Programs\Python\Python36\lib\site-packages\telegram\ext\updater.py", line 280, in polling_action_cb
    allowed_updates=allowed_updates)
  File "C:\Users\ito0010\AppData\Local\Programs\Python\Python36\lib\site-packages\telegram\bot.py", line 65, in decorator
    result = func(self, *args, **kwargs)
  File "C:\Users\ito0010\AppData\Local\Programs\Python\Python36\lib\site-packages\telegram\bot.py", line 1975, in get_updates
    result = self._request.post(url, data, timeout=float(read_latency) + float(timeout))
  File "C:\Users\ito0010\AppData\Local\Programs\Python\Python36\lib\site-packages\telegram\utils\request.py", line 309, in post
    headers={'Content-Type': 'application/json'})
  File "C:\Users\ito0010\AppData\Local\Programs\Python\Python36\lib\site-packages\telegram\utils\request.py", line 233, in _request_wrapper
    raise NetworkError('{0} ({1})'.format(message, resp.status))
telegram.error.NetworkError: Conflict: terminated by other getUpdates request; make sure that only one bot instance is running (409)
telegram.ext.updater - ERROR - Error while getting Updates: Conflict: terminated by other getUpdates request; make sure that only one bot instance is running (409)
telegram.ext.dispatcher - ERROR - No error handlers are registered, logging exception.
Traceback (most recent call last):
  File "C:\Users\ito0010\AppData\Local\Programs\Python\Python36\lib\site-packages\telegram\ext\updater.py", line 319, in _network_loop_retry
    if not action_cb():
  File "C:\Users\ito0010\AppData\Local\Programs\Python\Python36\lib\site-packages\telegram\ext\updater.py", line 280, in polling_action_cb
    allowed_updates=allowed_updates)
  File "C:\Users\ito0010\AppData\Local\Programs\Python\Python36\lib\site-packages\telegram\bot.py", line 65, in decorator
    result = func(self, *args, **kwargs)
  File "C:\Users\ito0010\AppData\Local\Programs\Python\Python36\lib\site-packages\telegram\bot.py", line 1975, in get_updates
    result = self._request.post(url, data, timeout=float(read_latency) + float(timeout))
  File "C:\Users\ito0010\AppData\Local\Programs\Python\Python36\lib\site-packages\telegram\utils\request.py", line 309, in post
    headers={'Content-Type': 'application/json'})
  File "C:\Users\ito0010\AppData\Local\Programs\Python\Python36\lib\site-packages\telegram\utils\request.py", line 233, in _request_wrapper
    raise NetworkError('{0} ({1})'.format(message, resp.status))
telegram.error.NetworkError: Conflict: terminated by other getUpdates request; make sure that only one bot instance is running (409)
telegram.ext.updater - INFO - Received signal 2 (SIGINT), stopping...
telegram.ext.updater - ERROR - Error while getting Updates: Conflict: terminated by other getUpdates request; make sure that only one bot instance is running (409)
telegram.ext.dispatcher - ERROR - An uncaught error was raised while processing the update
Traceback (most recent call last):
  File "C:\Users\ito0010\AppData\Local\Programs\Python\Python36\lib\site-packages\telegram\ext\dispatcher.py", line 279, in process_update
    handler.handle_update(update, self)
  File "C:\Users\ito0010\AppData\Local\Programs\Python\Python36\lib\site-packages\telegram\ext\commandhandler.py", line 173, in handle_update
    return self.callback(dispatcher.bot, update, **optional_args)
  File "c:\LearnPython\Lesson2\bot.py", line 30, in planet_user
    print(today)
NameError: name 'today' is not defined
telegram.ext.updater - INFO - Received signal 2 (SIGINT), stopping...
telegram.ext.dispatcher - ERROR - An uncaught error was raised while processing the update
Traceback (most recent call last):
  File "C:\Users\ito0010\AppData\Local\Programs\Python\Python36\lib\site-packages\telegram\ext\dispatcher.py", line 279, in process_update
    handler.handle_update(update, self)
  File "C:\Users\ito0010\AppData\Local\Programs\Python\Python36\lib\site-packages\telegram\ext\commandhandler.py", line 173, in handle_update
    return self.callback(dispatcher.bot, update, **optional_args)
  File "c:\LearnPython\Lesson2\bot.py", line 30, in planet_user
    print(today)
NameError: name 'today' is not defined
telegram.ext.updater - INFO - Received signal 2 (SIGINT), stopping...
telegram.ext.dispatcher - ERROR - An uncaught error was raised while processing the update
Traceback (most recent call last):
  File "C:\Users\ito0010\AppData\Local\Programs\Python\Python36\lib\site-packages\telegram\ext\dispatcher.py", line 279, in process_update
    handler.handle_update(update, self)
  File "C:\Users\ito0010\AppData\Local\Programs\Python\Python36\lib\site-packages\telegram\ext\commandhandler.py", line 173, in handle_update
    return self.callback(dispatcher.bot, update, **optional_args)
  File "c:\LearnPython\Lesson2\bot.py", line 33, in planet_user
    text = ephem.constellation(planet)
TypeError: you cannot ask about the constellation in which a body lies until you have used compute() to determine its position
telegram.ext.updater - INFO - Received signal 2 (SIGINT), stopping...
telegram.ext.updater - WARNING - Exiting immediately!
telegram.ext.dispatcher - ERROR - An uncaught error was raised while processing the update
Traceback (most recent call last):
  File "C:\Users\ito0010\AppData\Local\Programs\Python\Python36\lib\site-packages\telegram\ext\dispatcher.py", line 279, in process_update
    handler.handle_update(update, self)
  File "C:\Users\ito0010\AppData\Local\Programs\Python\Python36\lib\site-packages\telegram\ext\commandhandler.py", line 173, in handle_update
    return self.callback(dispatcher.bot, update, **optional_args)
  File "c:\LearnPython\Lesson2\bot.py", line 33, in planet_user
    text = ephem.constellation(planet)
TypeError: you cannot ask about the constellation in which a body lies until you have used compute() to determine its position
telegram.ext.updater - INFO - Received signal 2 (SIGINT), stopping...
telegram.ext.dispatcher - ERROR - An uncaught error was raised while processing the update
Traceback (most recent call last):
  File "C:\Users\ito0010\AppData\Local\Programs\Python\Python36\lib\site-packages\telegram\ext\dispatcher.py", line 279, in process_update
    handler.handle_update(update, self)
  File "C:\Users\ito0010\AppData\Local\Programs\Python\Python36\lib\site-packages\telegram\ext\commandhandler.py", line 173, in handle_update
    return self.callback(dispatcher.bot, update, **optional_args)
  File "c:\LearnPython\Lesson2\bot.py", line 28, in planet_user
    print(planet)
UnboundLocalError: local variable 'planet' referenced before assignment
telegram.ext.updater - INFO - Received signal 2 (SIGINT), stopping...
telegram.ext.dispatcher - ERROR - An uncaught error was raised while processing the update
Traceback (most recent call last):
  File "C:\Users\ito0010\AppData\Local\Programs\Python\Python36\lib\site-packages\telegram\ext\dispatcher.py", line 279, in process_update
    handler.handle_update(update, self)
  File "C:\Users\ito0010\AppData\Local\Programs\Python\Python36\lib\site-packages\telegram\ext\commandhandler.py", line 173, in handle_update
    return self.callback(dispatcher.bot, update, **optional_args)
  File "c:\LearnPython\Lesson2\bot.py", line 33, in planet_user
    text = ephem.constellation(planet)
TypeError: you cannot ask about the constellation in which a body lies until you have used compute() to determine its position
telegram.ext.updater - INFO - Received signal 2 (SIGINT), stopping...
telegram.ext.dispatcher - ERROR - An uncaught error was raised while processing the update
Traceback (most recent call last):
  File "C:\Users\ito0010\AppData\Local\Programs\Python\Python36\lib\site-packages\telegram\ext\dispatcher.py", line 279, in process_update
    handler.handle_update(update, self)
  File "C:\Users\ito0010\AppData\Local\Programs\Python\Python36\lib\site-packages\telegram\ext\commandhandler.py", line 173, in handle_update
    return self.callback(dispatcher.bot, update, **optional_args)
  File "c:\LearnPython\Lesson2\bot.py", line 33, in planet_user
    text = ephem.constellation(planet)
TypeError: you cannot ask about the constellation in which a body lies until you have used compute() to determine its position
telegram.ext.updater - INFO - Received signal 2 (SIGINT), stopping...
telegram.ext.dispatcher - ERROR - An uncaught error was raised while processing the update
Traceback (most recent call last):
  File "C:\Users\ito0010\AppData\Local\Programs\Python\Python36\lib\site-packages\telegram\ext\dispatcher.py", line 279, in process_update
    handler.handle_update(update, self)
  File "C:\Users\ito0010\AppData\Local\Programs\Python\Python36\lib\site-packages\telegram\ext\commandhandler.py", line 173, in handle_update
    return self.callback(dispatcher.bot, update, **optional_args)
  File "c:\LearnPython\Lesson2\bot.py", line 29, in planet_user
    today = datetime.strftime(datetime.now(), '%Y/%m/%d')
NameError: name 'datetime' is not defined
telegram.ext.updater - INFO - Received signal 2 (SIGINT), stopping...
telegram.ext.updater - WARNING - Exiting immediately!
telegram.ext.dispatcher - ERROR - An uncaught error was raised while processing the update
Traceback (most recent call last):
  File "C:\Users\ito0010\AppData\Local\Programs\Python\Python36\lib\site-packages\telegram\ext\dispatcher.py", line 279, in process_update
    handler.handle_update(update, self)
  File "C:\Users\ito0010\AppData\Local\Programs\Python\Python36\lib\site-packages\telegram\ext\commandhandler.py", line 173, in handle_update
    return self.callback(dispatcher.bot, update, **optional_args)
  File "c:\LearnPython\Lesson2\bot.py", line 29, in planet_user
    today = datetime.strftime(datetime.now(), '%Y/%m/%d')
AttributeError: module 'datetime' has no attribute 'strftime'
telegram.ext.updater - INFO - Received signal 2 (SIGINT), stopping...
telegram.ext.updater - WARNING - Exiting immediately!
telegram.ext.dispatcher - ERROR - An uncaught error was raised while processing the update
Traceback (most recent call last):
  File "C:\Users\ito0010\AppData\Local\Programs\Python\Python36\lib\site-packages\telegram\ext\dispatcher.py", line 279, in process_update
    handler.handle_update(update, self)
  File "C:\Users\ito0010\AppData\Local\Programs\Python\Python36\lib\site-packages\telegram\ext\commandhandler.py", line 173, in handle_update
    return self.callback(dispatcher.bot, update, **optional_args)
  File "c:\LearnPython\Lesson2\bot.py", line 34, in planet_user
    text = ephem.constellation(planet)
TypeError: you cannot ask about the constellation in which a body lies until you have used compute() to determine its position
telegram.ext.updater - INFO - Received signal 2 (SIGINT), stopping...
telegram.ext.updater - WARNING - Exiting immediately!
telegram.ext.dispatcher - ERROR - An uncaught error was raised while processing the update
Traceback (most recent call last):
  File "C:\Users\ito0010\AppData\Local\Programs\Python\Python36\lib\site-packages\telegram\ext\dispatcher.py", line 279, in process_update
    handler.handle_update(update, self)
  File "C:\Users\ito0010\AppData\Local\Programs\Python\Python36\lib\site-packages\telegram\ext\commandhandler.py", line 173, in handle_update
    return self.callback(dispatcher.bot, update, **optional_args)
  File "c:\LearnPython\Lesson2\bot.py", line 33, in planet_user
    planet = planet + ()
TypeError: unsupported operand type(s) for +: 'type' and 'tuple'
telegram.ext.updater - INFO - Received signal 2 (SIGINT), stopping...
telegram.ext.updater - WARNING - Exiting immediately!
telegram.ext.dispatcher - ERROR - An uncaught error was raised while processing the update
Traceback (most recent call last):
  File "C:\Users\ito0010\AppData\Local\Programs\Python\Python36\lib\site-packages\telegram\ext\dispatcher.py", line 279, in process_update
    handler.handle_update(update, self)
  File "C:\Users\ito0010\AppData\Local\Programs\Python\Python36\lib\site-packages\telegram\ext\commandhandler.py", line 173, in handle_update
    return self.callback(dispatcher.bot, update, **optional_args)
  File "c:\LearnPython\Lesson2\bot.py", line 33, in planet_user
    planet = planet + '()'
TypeError: unsupported operand type(s) for +: 'type' and 'str'
telegram.ext.updater - INFO - Received signal 2 (SIGINT), stopping...
telegram.ext.updater - WARNING - Exiting immediately!
telegram.ext.dispatcher - ERROR - An uncaught error was raised while processing the update
Traceback (most recent call last):
  File "C:\Users\ito0010\AppData\Local\Programs\Python\Python36\lib\site-packages\telegram\ext\dispatcher.py", line 279, in process_update
    handler.handle_update(update, self)
  File "C:\Users\ito0010\AppData\Local\Programs\Python\Python36\lib\site-packages\telegram\ext\commandhandler.py", line 173, in handle_update
    return self.callback(dispatcher.bot, update, **optional_args)
  File "c:\LearnPython\Lesson2\bot.py", line 33, in planet_user
    text = ephem.constellation(planet)
TypeError: you cannot ask about the constellation in which a body lies until you have used compute() to determine its position
telegram.ext.updater - ERROR - Error while getting Updates: Conflict: terminated by other getUpdates request; make sure that only one bot instance is running (409)
telegram.ext.dispatcher - ERROR - No error handlers are registered, logging exception.
Traceback (most recent call last):
  File "C:\Users\ito0010\AppData\Local\Programs\Python\Python36\lib\site-packages\telegram\ext\updater.py", line 319, in _network_loop_retry
    if not action_cb():
  File "C:\Users\ito0010\AppData\Local\Programs\Python\Python36\lib\site-packages\telegram\ext\updater.py", line 280, in polling_action_cb
    allowed_updates=allowed_updates)
  File "C:\Users\ito0010\AppData\Local\Programs\Python\Python36\lib\site-packages\telegram\bot.py", line 65, in decorator
    result = func(self, *args, **kwargs)
  File "C:\Users\ito0010\AppData\Local\Programs\Python\Python36\lib\site-packages\telegram\bot.py", line 1975, in get_updates
    result = self._request.post(url, data, timeout=float(read_latency) + float(timeout))
  File "C:\Users\ito0010\AppData\Local\Programs\Python\Python36\lib\site-packages\telegram\utils\request.py", line 309, in post
    headers={'Content-Type': 'application/json'})
  File "C:\Users\ito0010\AppData\Local\Programs\Python\Python36\lib\site-packages\telegram\utils\request.py", line 233, in _request_wrapper
    raise NetworkError('{0} ({1})'.format(message, resp.status))
telegram.error.NetworkError: Conflict: terminated by other getUpdates request; make sure that only one bot instance is running (409)
telegram.ext.updater - INFO - Received signal 2 (SIGINT), stopping...
telegram.ext.updater - WARNING - Exiting immediately!
telegram.ext.updater - ERROR - Error while getting Updates: Conflict: terminated by other getUpdates request; make sure that only one bot instance is running (409)
telegram.ext.dispatcher - ERROR - No error handlers are registered, logging exception.
Traceback (most recent call last):
  File "C:\Users\ito0010\AppData\Local\Programs\Python\Python36\lib\site-packages\telegram\ext\updater.py", line 319, in _network_loop_retry
    if not action_cb():
  File "C:\Users\ito0010\AppData\Local\Programs\Python\Python36\lib\site-packages\telegram\ext\updater.py", line 280, in polling_action_cb
    allowed_updates=allowed_updates)
  File "C:\Users\ito0010\AppData\Local\Programs\Python\Python36\lib\site-packages\telegram\bot.py", line 65, in decorator
    result = func(self, *args, **kwargs)
  File "C:\Users\ito0010\AppData\Local\Programs\Python\Python36\lib\site-packages\telegram\bot.py", line 1975, in get_updates
    result = self._request.post(url, data, timeout=float(read_latency) + float(timeout))
  File "C:\Users\ito0010\AppData\Local\Programs\Python\Python36\lib\site-packages\telegram\utils\request.py", line 309, in post
    headers={'Content-Type': 'application/json'})
  File "C:\Users\ito0010\AppData\Local\Programs\Python\Python36\lib\site-packages\telegram\utils\request.py", line 233, in _request_wrapper
    raise NetworkError('{0} ({1})'.format(message, resp.status))
telegram.error.NetworkError: Conflict: terminated by other getUpdates request; make sure that only one bot instance is running (409)
telegram.ext.dispatcher - ERROR - An uncaught error was raised while processing the update
Traceback (most recent call last):
  File "C:\Users\ito0010\AppData\Local\Programs\Python\Python36\lib\site-packages\telegram\ext\dispatcher.py", line 279, in process_update
    handler.handle_update(update, self)
  File "C:\Users\ito0010\AppData\Local\Programs\Python\Python36\lib\site-packages\telegram\ext\commandhandler.py", line 173, in handle_update
    return self.callback(dispatcher.bot, update, **optional_args)
  File "c:\LearnPython\Lesson2\bot.py", line 33, in planet_user
    ephem.compute()
TypeError: you cannot ask about the constellation in which a body lies until you have used compute() to determine its position
telegram.ext.updater - ERROR - Error while getting Updates: Conflict: terminated by other getUpdates request; make sure that only one bot instance is running (409)
telegram.ext.dispatcher - ERROR - No error handlers are registered, logging exception.
Traceback (most recent call last):
  File "C:\Users\ito0010\AppData\Local\Programs\Python\Python36\lib\site-packages\telegram\ext\updater.py", line 319, in _network_loop_retry
    if not action_cb():
  File "C:\Users\ito0010\AppData\Local\Programs\Python\Python36\lib\site-packages\telegram\ext\updater.py", line 280, in polling_action_cb
    allowed_updates=allowed_updates)
  File "C:\Users\ito0010\AppData\Local\Programs\Python\Python36\lib\site-packages\telegram\bot.py", line 65, in decorator
    result = func(self, *args, **kwargs)
  File "C:\Users\ito0010\AppData\Local\Programs\Python\Python36\lib\site-packages\telegram\bot.py", line 1975, in get_updates
    result = self._request.post(url, data, timeout=float(read_latency) + float(timeout))
  File "C:\Users\ito0010\AppData\Local\Programs\Python\Python36\lib\site-packages\telegram\utils\request.py", line 309, in post
    headers={'Content-Type': 'application/json'})
  File "C:\Users\ito0010\AppData\Local\Programs\Python\Python36\lib\site-packages\telegram\utils\request.py", line 233, in _request_wrapper
    raise NetworkError('{0} ({1})'.format(message, resp.status))
telegram.error.NetworkError: Conflict: terminated by other getUpdates request; make sure that only one bot instance is running (409)
telegram.ext.updater - ERROR - Error while getting Updates: Conflict: terminated by other getUpdates request; make sure that only one bot instance is running (409)
telegram.ext.dispatcher - ERROR - No error handlers are registered, logging exception.
Traceback (most recent call last):
  File "C:\Users\ito0010\AppData\Local\Programs\Python\Python36\lib\site-packages\telegram\ext\updater.py", line 319, in _network_loop_retry
    if not action_cb():
  File "C:\Users\ito0010\AppData\Local\Programs\Python\Python36\lib\site-packages\telegram\ext\updater.py", line 280, in polling_action_cb
    allowed_updates=allowed_updates)
  File "C:\Users\ito0010\AppData\Local\Programs\Python\Python36\lib\site-packages\telegram\bot.py", line 65, in decorator
    result = func(self, *args, **kwargs)
  File "C:\Users\ito0010\AppData\Local\Programs\Python\Python36\lib\site-packages\telegram\bot.py", line 1975, in get_updates
    result = self._request.post(url, data, timeout=float(read_latency) + float(timeout))
  File "C:\Users\ito0010\AppData\Local\Programs\Python\Python36\lib\site-packages\telegram\utils\request.py", line 309, in post
    headers={'Content-Type': 'application/json'})
  File "C:\Users\ito0010\AppData\Local\Programs\Python\Python36\lib\site-packages\telegram\utils\request.py", line 233, in _request_wrapper
    raise NetworkError('{0} ({1})'.format(message, resp.status))
telegram.error.NetworkError: Conflict: terminated by other getUpdates request; make sure that only one bot instance is running (409)
telegram.ext.updater - ERROR - Error while getting Updates: Conflict: terminated by other getUpdates request; make sure that only one bot instance is running (409)
telegram.ext.dispatcher - ERROR - No error handlers are registered, logging exception.
Traceback (most recent call last):
  File "C:\Users\ito0010\AppData\Local\Programs\Python\Python36\lib\site-packages\telegram\ext\updater.py", line 319, in _network_loop_retry
    if not action_cb():
  File "C:\Users\ito0010\AppData\Local\Programs\Python\Python36\lib\site-packages\telegram\ext\updater.py", line 280, in polling_action_cb
    allowed_updates=allowed_updates)
  File "C:\Users\ito0010\AppData\Local\Programs\Python\Python36\lib\site-packages\telegram\bot.py", line 65, in decorator
    result = func(self, *args, **kwargs)
  File "C:\Users\ito0010\AppData\Local\Programs\Python\Python36\lib\site-packages\telegram\bot.py", line 1975, in get_updates
    result = self._request.post(url, data, timeout=float(read_latency) + float(timeout))
  File "C:\Users\ito0010\AppData\Local\Programs\Python\Python36\lib\site-packages\telegram\utils\request.py", line 309, in post
    headers={'Content-Type': 'application/json'})
  File "C:\Users\ito0010\AppData\Local\Programs\Python\Python36\lib\site-packages\telegram\utils\request.py", line 233, in _request_wrapper
    raise NetworkError('{0} ({1})'.format(message, resp.status))
telegram.error.NetworkError: Conflict: terminated by other getUpdates request; make sure that only one bot instance is running (409)
telegram.ext.updater - ERROR - Error while getting Updates: Conflict: terminated by other getUpdates request; make sure that only one bot instance is running (409)
telegram.ext.dispatcher - ERROR - No error handlers are registered, logging exception.
Traceback (most recent call last):
  File "C:\Users\ito0010\AppData\Local\Programs\Python\Python36\lib\site-packages\telegram\ext\updater.py", line 319, in _network_loop_retry
    if not action_cb():
  File "C:\Users\ito0010\AppData\Local\Programs\Python\Python36\lib\site-packages\telegram\ext\updater.py", line 280, in polling_action_cb
    allowed_updates=allowed_updates)
  File "C:\Users\ito0010\AppData\Local\Programs\Python\Python36\lib\site-packages\telegram\bot.py", line 65, in decorator
    result = func(self, *args, **kwargs)
  File "C:\Users\ito0010\AppData\Local\Programs\Python\Python36\lib\site-packages\telegram\bot.py", line 1975, in get_updates
    result = self._request.post(url, data, timeout=float(read_latency) + float(timeout))
  File "C:\Users\ito0010\AppData\Local\Programs\Python\Python36\lib\site-packages\telegram\utils\request.py", line 309, in post
    headers={'Content-Type': 'application/json'})
  File "C:\Users\ito0010\AppData\Local\Programs\Python\Python36\lib\site-packages\telegram\utils\request.py", line 233, in _request_wrapper
    raise NetworkError('{0} ({1})'.format(message, resp.status))
telegram.error.NetworkError: Conflict: terminated by other getUpdates request; make sure that only one bot instance is running (409)
telegram.ext.updater - ERROR - Error while getting Updates: Conflict: terminated by other getUpdates request; make sure that only one bot instance is running (409)
telegram.ext.dispatcher - ERROR - No error handlers are registered, logging exception.
Traceback (most recent call last):
  File "C:\Users\ito0010\AppData\Local\Programs\Python\Python36\lib\site-packages\telegram\ext\updater.py", line 319, in _network_loop_retry
    if not action_cb():
  File "C:\Users\ito0010\AppData\Local\Programs\Python\Python36\lib\site-packages\telegram\ext\updater.py", line 280, in polling_action_cb
    allowed_updates=allowed_updates)
  File "C:\Users\ito0010\AppData\Local\Programs\Python\Python36\lib\site-packages\telegram\bot.py", line 65, in decorator
    result = func(self, *args, **kwargs)
  File "C:\Users\ito0010\AppData\Local\Programs\Python\Python36\lib\site-packages\telegram\bot.py", line 1975, in get_updates
    result = self._request.post(url, data, timeout=float(read_latency) + float(timeout))
  File "C:\Users\ito0010\AppData\Local\Programs\Python\Python36\lib\site-packages\telegram\utils\request.py", line 309, in post
    headers={'Content-Type': 'application/json'})
  File "C:\Users\ito0010\AppData\Local\Programs\Python\Python36\lib\site-packages\telegram\utils\request.py", line 233, in _request_wrapper
    raise NetworkError('{0} ({1})'.format(message, resp.status))
telegram.error.NetworkError: Conflict: terminated by other getUpdates request; make sure that only one bot instance is running (409)
telegram.ext.updater - INFO - Received signal 2 (SIGINT), stopping...
telegram.ext.updater - WARNING - Exiting immediately!
telegram.ext.updater - ERROR - Error while getting Updates: Conflict: terminated by other getUpdates request; make sure that only one bot instance is running (409)
telegram.ext.dispatcher - ERROR - No error handlers are registered, logging exception.
Traceback (most recent call last):
  File "C:\Users\ito0010\AppData\Local\Programs\Python\Python36\lib\site-packages\telegram\ext\updater.py", line 319, in _network_loop_retry
    if not action_cb():
  File "C:\Users\ito0010\AppData\Local\Programs\Python\Python36\lib\site-packages\telegram\ext\updater.py", line 280, in polling_action_cb
    allowed_updates=allowed_updates)
  File "C:\Users\ito0010\AppData\Local\Programs\Python\Python36\lib\site-packages\telegram\bot.py", line 65, in decorator
    result = func(self, *args, **kwargs)
  File "C:\Users\ito0010\AppData\Local\Programs\Python\Python36\lib\site-packages\telegram\bot.py", line 1975, in get_updates
    result = self._request.post(url, data, timeout=float(read_latency) + float(timeout))
  File "C:\Users\ito0010\AppData\Local\Programs\Python\Python36\lib\site-packages\telegram\utils\request.py", line 309, in post
    headers={'Content-Type': 'application/json'})
  File "C:\Users\ito0010\AppData\Local\Programs\Python\Python36\lib\site-packages\telegram\utils\request.py", line 233, in _request_wrapper
    raise NetworkError('{0} ({1})'.format(message, resp.status))
telegram.error.NetworkError: Conflict: terminated by other getUpdates request; make sure that only one bot instance is running (409)
telegram.ext.dispatcher - ERROR - An uncaught error was raised while processing the update
Traceback (most recent call last):
  File "C:\Users\ito0010\AppData\Local\Programs\Python\Python36\lib\site-packages\telegram\ext\dispatcher.py", line 279, in process_update
    handler.handle_update(update, self)
  File "C:\Users\ito0010\AppData\Local\Programs\Python\Python36\lib\site-packages\telegram\ext\commandhandler.py", line 173, in handle_update
    return self.callback(dispatcher.bot, update, **optional_args)
  File "c:\LearnPython\Lesson2\bot.py", line 33, in planet_user
    ephem.compute()
AttributeError: module 'ephem' has no attribute 'compute'
telegram.ext.updater - INFO - Received signal 2 (SIGINT), stopping...
telegram.ext.updater - WARNING - Exiting immediately!
telegram.ext.dispatcher - ERROR - An uncaught error was raised while processing the update
Traceback (most recent call last):
  File "C:\Users\ito0010\AppData\Local\Programs\Python\Python36\lib\site-packages\telegram\ext\dispatcher.py", line 279, in process_update
    handler.handle_update(update, self)
  File "C:\Users\ito0010\AppData\Local\Programs\Python\Python36\lib\site-packages\telegram\ext\commandhandler.py", line 173, in handle_update
    return self.callback(dispatcher.bot, update, **optional_args)
  File "c:\LearnPython\Lesson2\bot.py", line 33, in planet_user
    text = ephem.constellation(planet)
TypeError: you cannot ask about the constellation in which a body lies until you have used compute() to determine its position
telegram.ext.updater - INFO - Received signal 2 (SIGINT), stopping...
telegram.ext.updater - WARNING - Exiting immediately!
telegram.ext.dispatcher - ERROR - An uncaught error was raised while processing the update
Traceback (most recent call last):
  File "C:\Users\ito0010\AppData\Local\Programs\Python\Python36\lib\site-packages\telegram\ext\dispatcher.py", line 279, in process_update
    handler.handle_update(update, self)
  File "C:\Users\ito0010\AppData\Local\Programs\Python\Python36\lib\site-packages\telegram\ext\commandhandler.py", line 173, in handle_update
    return self.callback(dispatcher.bot, update, **optional_args)
  File "c:\LearnPython\Lesson2\bot.py", line 29, in planet_user
    today = datetime.strftime(datetime.now(), '%Y/%m/%d')
AttributeError: module 'datetime' has no attribute 'strftime'
telegram.ext.updater - INFO - Received signal 2 (SIGINT), stopping...
telegram.ext.updater - WARNING - Exiting immediately!
telegram.ext.updater - INFO - Received signal 2 (SIGINT), stopping...
